Ignoring exception in command music
Traceback (most recent call last):
  File "C:\Users\ProPCUser\PycharmProjects\lycproject\venv\lib\site-packages\discord\app_commands\commands.py", line 827, in _do_call
    return await self._callback(self.binding, interaction, **params)  # type: ignore
  File "C:\Users\ProPCUser\PycharmProjects\lycproject\cogs\music_bot.py", line 93, in music
    await ctx.send(f"Играет {get_song_name(url)}, запрошенное {ctx.message.author.mention}")
  File "C:\Users\ProPCUser\PycharmProjects\lycproject\venv\lib\site-packages\discord\ext\commands\context.py", line 1060, in send
    await self.interaction.response.send_message(**kwargs)
  File "C:\Users\ProPCUser\PycharmProjects\lycproject\venv\lib\site-packages\discord\interactions.py", line 801, in send_message
    await adapter.create_interaction_response(
  File "C:\Users\ProPCUser\PycharmProjects\lycproject\venv\lib\site-packages\discord\webhook\async_.py", line 219, in request
    raise NotFound(response, data)
discord.errors.NotFound: 404 Not Found (error code: 10062): Unknown interaction

The above exception was the direct cause of the following exception:

Traceback (most recent call last):
  File "C:\Users\ProPCUser\PycharmProjects\lycproject\venv\lib\site-packages\discord\ext\commands\hybrid.py", line 438, in _invoke_with_namespace
    value = await self._do_call(ctx, ctx.kwargs)  # type: ignore
  File "C:\Users\ProPCUser\PycharmProjects\lycproject\venv\lib\site-packages\discord\app_commands\commands.py", line 846, in _do_call
    raise CommandInvokeError(self, e) from e
discord.app_commands.errors.CommandInvokeError: Command 'music' raised an exception: NotFound: 404 Not Found (error code: 10062): Unknown interaction

The above exception was the direct cause of the following exception:

Traceback (most recent call last):
  File "C:\Users\ProPCUser\PycharmProjects\lycproject\venv\lib\site-packages\discord\ext\commands\hybrid.py", line 438, in _invoke_with_namespace
    value = await self._do_call(ctx, ctx.kwargs)  # type: ignore
  File "C:\Users\ProPCUser\PycharmProjects\lycproject\venv\lib\site-packages\discord\app_commands\commands.py", line 846, in _do_call
    raise CommandInvokeError(self, e) from e
discord.ext.commands.errors.HybridCommandError: Hybrid command raised an error: Command 'music' raised an exception: NotFound: 404 Not Found (error code: 10062): Unknown interaction
Ignoring exception in command song
Traceback (most recent call last):
  File "C:\Users\ProPCUser\PycharmProjects\lycproject\venv\lib\site-packages\discord\ext\commands\hybrid.py", line 436, in _invoke_with_namespace
    await command.prepare(ctx)
  File "C:\Users\ProPCUser\PycharmProjects\lycproject\venv\lib\site-packages\discord\ext\commands\core.py", line 925, in prepare
    if not await self.can_run(ctx):
  File "C:\Users\ProPCUser\PycharmProjects\lycproject\venv\lib\site-packages\discord\ext\commands\hybrid.py", line 524, in can_run
    return await self.app_command._check_can_run(ctx.interaction)
  File "C:\Users\ProPCUser\PycharmProjects\lycproject\venv\lib\site-packages\discord\ext\commands\hybrid.py", line 415, in _check_can_run
    if self.checks and not await async_all(f(interaction) for f in self.checks):
  File "C:\Users\ProPCUser\PycharmProjects\lycproject\venv\lib\site-packages\discord\utils.py", line 703, in async_all
    for elem in gen:
  File "C:\Users\ProPCUser\PycharmProjects\lycproject\venv\lib\site-packages\discord\ext\commands\hybrid.py", line 415, in <genexpr>
    if self.checks and not await async_all(f(interaction) for f in self.checks):
  File "C:\Users\ProPCUser\PycharmProjects\lycproject\venv\lib\site-packages\discord\app_commands\checks.py", line 232, in predicate
    raise MissingRole(item)
discord.app_commands.errors.MissingRole: Role 1232060135908835348 is required to run this command.

The above exception was the direct cause of the following exception:

Traceback (most recent call last):
  File "C:\Users\ProPCUser\PycharmProjects\lycproject\venv\lib\site-packages\discord\ext\commands\hybrid.py", line 436, in _invoke_with_namespace
    await command.prepare(ctx)
  File "C:\Users\ProPCUser\PycharmProjects\lycproject\venv\lib\site-packages\discord\ext\commands\core.py", line 925, in prepare
    if not await self.can_run(ctx):
  File "C:\Users\ProPCUser\PycharmProjects\lycproject\venv\lib\site-packages\discord\ext\commands\hybrid.py", line 524, in can_run
    return await self.app_command._check_can_run(ctx.interaction)
  File "C:\Users\ProPCUser\PycharmProjects\lycproject\venv\lib\site-packages\discord\ext\commands\hybrid.py", line 415, in _check_can_run
    if self.checks and not await async_all(f(interaction) for f in self.checks):
  File "C:\Users\ProPCUser\PycharmProjects\lycproject\venv\lib\site-packages\discord\utils.py", line 703, in async_all
    for elem in gen:
  File "C:\Users\ProPCUser\PycharmProjects\lycproject\venv\lib\site-packages\discord\ext\commands\hybrid.py", line 415, in <genexpr>
    if self.checks and not await async_all(f(interaction) for f in self.checks):
  File "C:\Users\ProPCUser\PycharmProjects\lycproject\venv\lib\site-packages\discord\app_commands\checks.py", line 232, in predicate
    raise MissingRole(item)
discord.ext.commands.errors.HybridCommandError: Hybrid command raised an error: Role 1232060135908835348 is required to run this command.
Ignoring exception in command song
Traceback (most recent call last):
  File "C:\Users\ProPCUser\PycharmProjects\lycproject\venv\lib\site-packages\discord\app_commands\commands.py", line 827, in _do_call
    return await self._callback(self.binding, interaction, **params)  # type: ignore
  File "C:\Users\ProPCUser\PycharmProjects\lycproject\cogs\dev_cogs.py", line 48, in music
    await ctx.send(f'Сейчас играет: "{self.title}"')
  File "C:\Users\ProPCUser\PycharmProjects\lycproject\venv\lib\site-packages\discord\ext\commands\context.py", line 1060, in send
    await self.interaction.response.send_message(**kwargs)
  File "C:\Users\ProPCUser\PycharmProjects\lycproject\venv\lib\site-packages\discord\interactions.py", line 801, in send_message
    await adapter.create_interaction_response(
  File "C:\Users\ProPCUser\PycharmProjects\lycproject\venv\lib\site-packages\discord\webhook\async_.py", line 219, in request
    raise NotFound(response, data)
discord.errors.NotFound: 404 Not Found (error code: 10062): Unknown interaction

The above exception was the direct cause of the following exception:

Traceback (most recent call last):
  File "C:\Users\ProPCUser\PycharmProjects\lycproject\venv\lib\site-packages\discord\ext\commands\hybrid.py", line 438, in _invoke_with_namespace
    value = await self._do_call(ctx, ctx.kwargs)  # type: ignore
  File "C:\Users\ProPCUser\PycharmProjects\lycproject\venv\lib\site-packages\discord\app_commands\commands.py", line 846, in _do_call
    raise CommandInvokeError(self, e) from e
discord.app_commands.errors.CommandInvokeError: Command 'song' raised an exception: NotFound: 404 Not Found (error code: 10062): Unknown interaction

The above exception was the direct cause of the following exception:

Traceback (most recent call last):
  File "C:\Users\ProPCUser\PycharmProjects\lycproject\venv\lib\site-packages\discord\ext\commands\hybrid.py", line 438, in _invoke_with_namespace
    value = await self._do_call(ctx, ctx.kwargs)  # type: ignore
  File "C:\Users\ProPCUser\PycharmProjects\lycproject\venv\lib\site-packages\discord\app_commands\commands.py", line 846, in _do_call
    raise CommandInvokeError(self, e) from e
discord.ext.commands.errors.HybridCommandError: Hybrid command raised an error: Command 'song' raised an exception: NotFound: 404 Not Found (error code: 10062): Unknown interaction
Ignoring exception in command add_queue
Traceback (most recent call last):
  File "C:\Users\ProPCUser\PycharmProjects\lycproject\venv\lib\site-packages\discord\ext\commands\core.py", line 235, in wrapped
    ret = await coro(*args, **kwargs)
  File "C:\Users\ProPCUser\PycharmProjects\lycproject\cogs\music_bot.py", line 124, in add_queue
    embed = await self.quembed_ini(ctx)
  File "C:\Users\ProPCUser\PycharmProjects\lycproject\cogs\music_bot.py", line 75, in quembed_ini
    fields = [(str(self.queue[elem]), get_song_name(elem.url), False) for elem in self.queue.keys()]
  File "C:\Users\ProPCUser\PycharmProjects\lycproject\cogs\music_bot.py", line 75, in <listcomp>
    fields = [(str(self.queue[elem]), get_song_name(elem.url), False) for elem in self.queue.keys()]
AttributeError: 'str' object has no attribute 'url'

The above exception was the direct cause of the following exception:

Traceback (most recent call last):
  File "C:\Users\ProPCUser\PycharmProjects\lycproject\venv\lib\site-packages\discord\ext\commands\bot.py", line 1350, in invoke
    await ctx.command.invoke(ctx)
  File "C:\Users\ProPCUser\PycharmProjects\lycproject\venv\lib\site-packages\discord\ext\commands\core.py", line 1029, in invoke
    await injected(*ctx.args, **ctx.kwargs)  # type: ignore
  File "C:\Users\ProPCUser\PycharmProjects\lycproject\venv\lib\site-packages\discord\ext\commands\core.py", line 244, in wrapped
    raise CommandInvokeError(exc) from exc
discord.ext.commands.errors.CommandInvokeError: Command raised an exception: AttributeError: 'str' object has no attribute 'url'
Ignoring exception in command add_queue
Traceback (most recent call last):
  File "C:\Users\ProPCUser\PycharmProjects\lycproject\venv\lib\site-packages\discord\ext\commands\core.py", line 235, in wrapped
    ret = await coro(*args, **kwargs)
  File "C:\Users\ProPCUser\PycharmProjects\lycproject\cogs\music_bot.py", line 125, in add_queue
    self.queue[url] = user
  File "C:\Users\ProPCUser\PycharmProjects\lycproject\cogs\music_bot.py", line 76, in quembed_ini
    fields = [(str(self.queue[elem]), get_song_name(elem.url), False) for elem in self.queue.keys()]
  File "C:\Users\ProPCUser\PycharmProjects\lycproject\cogs\music_bot.py", line 76, in <listcomp>
    fields = [(str(self.queue[elem]), get_song_name(elem.url), False) for elem in self.queue.keys()]
AttributeError: 'str' object has no attribute 'url'

The above exception was the direct cause of the following exception:

Traceback (most recent call last):
  File "C:\Users\ProPCUser\PycharmProjects\lycproject\venv\lib\site-packages\discord\ext\commands\bot.py", line 1350, in invoke
    await ctx.command.invoke(ctx)
  File "C:\Users\ProPCUser\PycharmProjects\lycproject\venv\lib\site-packages\discord\ext\commands\core.py", line 1029, in invoke
    await injected(*ctx.args, **ctx.kwargs)  # type: ignore
  File "C:\Users\ProPCUser\PycharmProjects\lycproject\venv\lib\site-packages\discord\ext\commands\core.py", line 244, in wrapped
    raise CommandInvokeError(exc) from exc
discord.ext.commands.errors.CommandInvokeError: Command raised an exception: AttributeError: 'str' object has no attribute 'url'
Ignoring exception in command add_queue
Traceback (most recent call last):
  File "C:\Users\ProPCUser\PycharmProjects\lycproject\venv\lib\site-packages\discord\ext\commands\core.py", line 235, in wrapped
    ret = await coro(*args, **kwargs)
  File "C:\Users\ProPCUser\PycharmProjects\lycproject\cogs\music_bot.py", line 126, in add_queue
    await ctx.send(embed=embed)
  File "C:\Users\ProPCUser\PycharmProjects\lycproject\cogs\music_bot.py", line 76, in quembed_ini
    fields.append(('Статус', status, True))
  File "C:\Users\ProPCUser\PycharmProjects\lycproject\cogs\music_bot.py", line 76, in <listcomp>
    fields.append(('Статус', status, True))
AttributeError: 'str' object has no attribute 'url'

The above exception was the direct cause of the following exception:

Traceback (most recent call last):
  File "C:\Users\ProPCUser\PycharmProjects\lycproject\venv\lib\site-packages\discord\ext\commands\bot.py", line 1350, in invoke
    await ctx.command.invoke(ctx)
  File "C:\Users\ProPCUser\PycharmProjects\lycproject\venv\lib\site-packages\discord\ext\commands\core.py", line 1029, in invoke
    await injected(*ctx.args, **ctx.kwargs)  # type: ignore
  File "C:\Users\ProPCUser\PycharmProjects\lycproject\venv\lib\site-packages\discord\ext\commands\core.py", line 244, in wrapped
    raise CommandInvokeError(exc) from exc
discord.ext.commands.errors.CommandInvokeError: Command raised an exception: AttributeError: 'str' object has no attribute 'url'
Ignoring exception in command add_queue
Traceback (most recent call last):
  File "C:\Users\ProPCUser\PycharmProjects\lycproject\venv\lib\site-packages\discord\ext\commands\core.py", line 235, in wrapped
    ret = await coro(*args, **kwargs)
  File "C:\Users\ProPCUser\PycharmProjects\lycproject\cogs\music_bot.py", line 126, in add_queue
    embed = await self.quembed_ini(ctx)
  File "C:\Users\ProPCUser\PycharmProjects\lycproject\cogs\music_bot.py", line 76, in quembed_ini
    fields = [(str(self.queue[elem]), get_song_name(elem.url), False) for elem in list(self.queue.keys())]
  File "C:\Users\ProPCUser\PycharmProjects\lycproject\cogs\music_bot.py", line 76, in <listcomp>
    fields = [(str(self.queue[elem]), get_song_name(elem.url), False) for elem in list(self.queue.keys())]
AttributeError: 'str' object has no attribute 'url'

The above exception was the direct cause of the following exception:

Traceback (most recent call last):
  File "C:\Users\ProPCUser\PycharmProjects\lycproject\venv\lib\site-packages\discord\ext\commands\bot.py", line 1350, in invoke
    await ctx.command.invoke(ctx)
  File "C:\Users\ProPCUser\PycharmProjects\lycproject\venv\lib\site-packages\discord\ext\commands\core.py", line 1029, in invoke
    await injected(*ctx.args, **ctx.kwargs)  # type: ignore
  File "C:\Users\ProPCUser\PycharmProjects\lycproject\venv\lib\site-packages\discord\ext\commands\core.py", line 244, in wrapped
    raise CommandInvokeError(exc) from exc
discord.ext.commands.errors.CommandInvokeError: Command raised an exception: AttributeError: 'str' object has no attribute 'url'
Ignoring exception in command add_queue
Traceback (most recent call last):
  File "C:\Users\ProPCUser\PycharmProjects\lycproject\venv\lib\site-packages\discord\ext\commands\core.py", line 235, in wrapped
    ret = await coro(*args, **kwargs)
  File "C:\Users\ProPCUser\PycharmProjects\lycproject\cogs\music_bot.py", line 127, in add_queue
    embed = await self.quembed_ini(ctx)
  File "C:\Users\ProPCUser\PycharmProjects\lycproject\cogs\music_bot.py", line 77, in quembed_ini
    fields = [(str(self.queue[elem]), get_song_name(elem.url), False) for elem in list(self.queue.keys())]
  File "C:\Users\ProPCUser\PycharmProjects\lycproject\cogs\music_bot.py", line 77, in <listcomp>
    fields = [(str(self.queue[elem]), get_song_name(elem.url), False) for elem in list(self.queue.keys())]
AttributeError: 'str' object has no attribute 'url'

The above exception was the direct cause of the following exception:

Traceback (most recent call last):
  File "C:\Users\ProPCUser\PycharmProjects\lycproject\venv\lib\site-packages\discord\ext\commands\bot.py", line 1350, in invoke
    await ctx.command.invoke(ctx)
  File "C:\Users\ProPCUser\PycharmProjects\lycproject\venv\lib\site-packages\discord\ext\commands\core.py", line 1029, in invoke
    await injected(*ctx.args, **ctx.kwargs)  # type: ignore
  File "C:\Users\ProPCUser\PycharmProjects\lycproject\venv\lib\site-packages\discord\ext\commands\core.py", line 244, in wrapped
    raise CommandInvokeError(exc) from exc
discord.ext.commands.errors.CommandInvokeError: Command raised an exception: AttributeError: 'str' object has no attribute 'url'
Ignoring exception in command music
Traceback (most recent call last):
  File "C:\Users\ProPCUser\PycharmProjects\lycproject\venv\lib\site-packages\discord\ext\commands\core.py", line 235, in wrapped
    ret = await coro(*args, **kwargs)
  File "C:\Users\ProPCUser\PycharmProjects\lycproject\cogs\music_bot.py", line 104, in music
    embed = await self.quembed_ini(ctx)
  File "C:\Users\ProPCUser\PycharmProjects\lycproject\cogs\music_bot.py", line 77, in quembed_ini
    fields = [(str(self.queue[elem]), get_song_name(elem), False) for elem in list(self.queue.keys())]
  File "C:\Users\ProPCUser\PycharmProjects\lycproject\cogs\music_bot.py", line 77, in <listcomp>
    fields = [(str(self.queue[elem]), get_song_name(elem), False) for elem in list(self.queue.keys())]
  File "C:\Users\ProPCUser\PycharmProjects\lycproject\yt_api.py", line 18, in get_song_name
    r = requests.get(request)
  File "C:\Users\ProPCUser\PycharmProjects\lycproject\venv\lib\site-packages\requests\api.py", line 73, in get
    return request("get", url, params=params, **kwargs)
  File "C:\Users\ProPCUser\PycharmProjects\lycproject\venv\lib\site-packages\requests\api.py", line 59, in request
    return session.request(method=method, url=url, **kwargs)
  File "C:\Users\ProPCUser\PycharmProjects\lycproject\venv\lib\site-packages\requests\sessions.py", line 575, in request
    prep = self.prepare_request(req)
  File "C:\Users\ProPCUser\PycharmProjects\lycproject\venv\lib\site-packages\requests\sessions.py", line 486, in prepare_request
    p.prepare(
  File "C:\Users\ProPCUser\PycharmProjects\lycproject\venv\lib\site-packages\requests\models.py", line 368, in prepare
    self.prepare_url(url, params)
  File "C:\Users\ProPCUser\PycharmProjects\lycproject\venv\lib\site-packages\requests\models.py", line 439, in prepare_url
    raise MissingSchema(
requests.exceptions.MissingSchema: Invalid URL '<cogs.music_bot.YtSource object at 0x000001F680401880>': No scheme supplied. Perhaps you meant https://<cogs.music_bot.YtSource object at 0x000001F680401880>?

The above exception was the direct cause of the following exception:

Traceback (most recent call last):
  File "C:\Users\ProPCUser\PycharmProjects\lycproject\venv\lib\site-packages\discord\ext\commands\bot.py", line 1350, in invoke
    await ctx.command.invoke(ctx)
  File "C:\Users\ProPCUser\PycharmProjects\lycproject\venv\lib\site-packages\discord\ext\commands\core.py", line 1029, in invoke
    await injected(*ctx.args, **ctx.kwargs)  # type: ignore
  File "C:\Users\ProPCUser\PycharmProjects\lycproject\venv\lib\site-packages\discord\ext\commands\core.py", line 244, in wrapped
    raise CommandInvokeError(exc) from exc
discord.ext.commands.errors.CommandInvokeError: Command raised an exception: MissingSchema: Invalid URL '<cogs.music_bot.YtSource object at 0x000001F680401880>': No scheme supplied. Perhaps you meant https://<cogs.music_bot.YtSource object at 0x000001F680401880>?
Ignoring exception in command add_queue
Traceback (most recent call last):
  File "C:\Users\ProPCUser\PycharmProjects\lycproject\venv\lib\site-packages\discord\ext\commands\core.py", line 235, in wrapped
    ret = await coro(*args, **kwargs)
  File "C:\Users\ProPCUser\PycharmProjects\lycproject\cogs\music_bot.py", line 127, in add_queue
    embed = await self.quembed_ini(ctx)
  File "C:\Users\ProPCUser\PycharmProjects\lycproject\cogs\music_bot.py", line 77, in quembed_ini
    fields = [(str(self.queue[elem]), get_song_name(elem), False) for elem in list(self.queue.keys())]
  File "C:\Users\ProPCUser\PycharmProjects\lycproject\cogs\music_bot.py", line 77, in <listcomp>
    fields = [(str(self.queue[elem]), get_song_name(elem), False) for elem in list(self.queue.keys())]
  File "C:\Users\ProPCUser\PycharmProjects\lycproject\yt_api.py", line 18, in get_song_name
    r = requests.get(request)
  File "C:\Users\ProPCUser\PycharmProjects\lycproject\venv\lib\site-packages\requests\api.py", line 73, in get
    return request("get", url, params=params, **kwargs)
  File "C:\Users\ProPCUser\PycharmProjects\lycproject\venv\lib\site-packages\requests\api.py", line 59, in request
    return session.request(method=method, url=url, **kwargs)
  File "C:\Users\ProPCUser\PycharmProjects\lycproject\venv\lib\site-packages\requests\sessions.py", line 575, in request
    prep = self.prepare_request(req)
  File "C:\Users\ProPCUser\PycharmProjects\lycproject\venv\lib\site-packages\requests\sessions.py", line 486, in prepare_request
    p.prepare(
  File "C:\Users\ProPCUser\PycharmProjects\lycproject\venv\lib\site-packages\requests\models.py", line 368, in prepare
    self.prepare_url(url, params)
  File "C:\Users\ProPCUser\PycharmProjects\lycproject\venv\lib\site-packages\requests\models.py", line 439, in prepare_url
    raise MissingSchema(
requests.exceptions.MissingSchema: Invalid URL '<cogs.music_bot.YtSource object at 0x000001F680401880>': No scheme supplied. Perhaps you meant https://<cogs.music_bot.YtSource object at 0x000001F680401880>?

The above exception was the direct cause of the following exception:

Traceback (most recent call last):
  File "C:\Users\ProPCUser\PycharmProjects\lycproject\venv\lib\site-packages\discord\ext\commands\bot.py", line 1350, in invoke
    await ctx.command.invoke(ctx)
  File "C:\Users\ProPCUser\PycharmProjects\lycproject\venv\lib\site-packages\discord\ext\commands\core.py", line 1029, in invoke
    await injected(*ctx.args, **ctx.kwargs)  # type: ignore
  File "C:\Users\ProPCUser\PycharmProjects\lycproject\venv\lib\site-packages\discord\ext\commands\core.py", line 244, in wrapped
    raise CommandInvokeError(exc) from exc
discord.ext.commands.errors.CommandInvokeError: Command raised an exception: MissingSchema: Invalid URL '<cogs.music_bot.YtSource object at 0x000001F680401880>': No scheme supplied. Perhaps you meant https://<cogs.music_bot.YtSource object at 0x000001F680401880>?
Ignoring exception in on_member_join
Traceback (most recent call last):
  File "C:\Users\ProPCUser\PycharmProjects\lycproject\venv\lib\site-packages\discord\client.py", line 441, in _run_event
    await coro(*args, **kwargs)
  File "C:\Users\ProPCUser\PycharmProjects\lycproject\cogs\default_cogs.py", line 38, in on_member_join
    dmchannel = await self.bot.create_dm(message.author)
AttributeError: 'Member' object has no attribute 'author'
Ignoring exception in on_member_join
Traceback (most recent call last):
  File "C:\Users\ProPCUser\PycharmProjects\lycproject\venv\lib\site-packages\discord\client.py", line 441, in _run_event
    await coro(*args, **kwargs)
  File "C:\Users\ProPCUser\PycharmProjects\lycproject\cogs\default_cogs.py", line 40, in on_member_join
    message.channel.send("ИДИ НАХУЙ ОТСЮДОВА!!!", embed=discord.Embed(colour=discord.Colour.dark_embed()))
AttributeError: 'Member' object has no attribute 'channel'
Ignoring exception in on_member_join
Traceback (most recent call last):
  File "C:\Users\ProPCUser\PycharmProjects\lycproject\venv\lib\site-packages\discord\client.py", line 441, in _run_event
    await coro(*args, **kwargs)
  File "C:\Users\ProPCUser\PycharmProjects\lycproject\cogs\default_cogs.py", line 42, in on_member_join
    f'{dt.datetime.now().strftime("%Y-%m-%d %H:%M")} {self.bot.user} ответил "{reply}" на сообщение "{message.content}" '
NameError: name 'reply' is not defined
Ignoring exception in on_member_join
Traceback (most recent call last):
  File "C:\Users\ProPCUser\PycharmProjects\lycproject\venv\lib\site-packages\discord\client.py", line 441, in _run_event
    await coro(*args, **kwargs)
  File "C:\Users\ProPCUser\PycharmProjects\lycproject\cogs\default_cogs.py", line 40, in on_member_join
    await member.guild.system_channel.send("ИДИ НАХУЙ ОТСЮДОВА!!!", embed=discord.Embed(colour=discord.Colour.dark_embed()))
  File "C:\Users\ProPCUser\PycharmProjects\lycproject\venv\lib\site-packages\discord\abc.py", line 1561, in send
    data = await state.http.send_message(channel.id, params=params)
  File "C:\Users\ProPCUser\PycharmProjects\lycproject\venv\lib\site-packages\discord\http.py", line 745, in request
    raise HTTPException(response, data)
discord.errors.HTTPException: 400 Bad Request (error code: 50035): Invalid Form Body
In embeds.0.description: This field is required
Ignoring exception in command music
Traceback (most recent call last):
  File "C:\Users\ProPCUser\PycharmProjects\lycproject\venv\lib\site-packages\discord\ext\commands\bot.py", line 1350, in invoke
    await ctx.command.invoke(ctx)
  File "C:\Users\ProPCUser\PycharmProjects\lycproject\venv\lib\site-packages\discord\ext\commands\core.py", line 1021, in invoke
    await self.prepare(ctx)
  File "C:\Users\ProPCUser\PycharmProjects\lycproject\venv\lib\site-packages\discord\ext\commands\core.py", line 938, in prepare
    await self._parse_arguments(ctx)
  File "C:\Users\ProPCUser\PycharmProjects\lycproject\venv\lib\site-packages\discord\ext\commands\core.py", line 845, in _parse_arguments
    transformed = await self.transform(ctx, param, attachments)
  File "C:\Users\ProPCUser\PycharmProjects\lycproject\venv\lib\site-packages\discord\ext\commands\core.py", line 697, in transform
    raise MissingRequiredArgument(param)
discord.ext.commands.errors.MissingRequiredArgument: url is a required argument that is missing.
Ignoring exception in command music
Traceback (most recent call last):
  File "C:\Users\ProPCUser\PycharmProjects\lycproject\venv\lib\site-packages\discord\ext\commands\core.py", line 235, in wrapped
    ret = await coro(*args, **kwargs)
  File "C:\Users\ProPCUser\PycharmProjects\lycproject\cogs\music_bot.py", line 105, in music
    embed = await self.quembed_ini(ctx)
  File "C:\Users\ProPCUser\PycharmProjects\lycproject\cogs\music_bot.py", line 78, in quembed_ini
    fields = [(str(self.queue[elem]), get_song_name(elem), False) for elem in list(self.queue.keys())]
  File "C:\Users\ProPCUser\PycharmProjects\lycproject\cogs\music_bot.py", line 78, in <listcomp>
    fields = [(str(self.queue[elem]), get_song_name(elem), False) for elem in list(self.queue.keys())]
  File "C:\Users\ProPCUser\PycharmProjects\lycproject\yt_api.py", line 18, in get_song_name
    r = requests.get(request)
  File "C:\Users\ProPCUser\PycharmProjects\lycproject\venv\lib\site-packages\requests\api.py", line 73, in get
    return request("get", url, params=params, **kwargs)
  File "C:\Users\ProPCUser\PycharmProjects\lycproject\venv\lib\site-packages\requests\api.py", line 59, in request
    return session.request(method=method, url=url, **kwargs)
  File "C:\Users\ProPCUser\PycharmProjects\lycproject\venv\lib\site-packages\requests\sessions.py", line 575, in request
    prep = self.prepare_request(req)
  File "C:\Users\ProPCUser\PycharmProjects\lycproject\venv\lib\site-packages\requests\sessions.py", line 486, in prepare_request
    p.prepare(
  File "C:\Users\ProPCUser\PycharmProjects\lycproject\venv\lib\site-packages\requests\models.py", line 368, in prepare
    self.prepare_url(url, params)
  File "C:\Users\ProPCUser\PycharmProjects\lycproject\venv\lib\site-packages\requests\models.py", line 439, in prepare_url
    raise MissingSchema(
requests.exceptions.MissingSchema: Invalid URL '<cogs.music_bot.YtSource object at 0x000001D1EE7F1E80>': No scheme supplied. Perhaps you meant https://<cogs.music_bot.YtSource object at 0x000001D1EE7F1E80>?

The above exception was the direct cause of the following exception:

Traceback (most recent call last):
  File "C:\Users\ProPCUser\PycharmProjects\lycproject\venv\lib\site-packages\discord\ext\commands\bot.py", line 1350, in invoke
    await ctx.command.invoke(ctx)
  File "C:\Users\ProPCUser\PycharmProjects\lycproject\venv\lib\site-packages\discord\ext\commands\core.py", line 1029, in invoke
    await injected(*ctx.args, **ctx.kwargs)  # type: ignore
  File "C:\Users\ProPCUser\PycharmProjects\lycproject\venv\lib\site-packages\discord\ext\commands\core.py", line 244, in wrapped
    raise CommandInvokeError(exc) from exc
discord.ext.commands.errors.CommandInvokeError: Command raised an exception: MissingSchema: Invalid URL '<cogs.music_bot.YtSource object at 0x000001D1EE7F1E80>': No scheme supplied. Perhaps you meant https://<cogs.music_bot.YtSource object at 0x000001D1EE7F1E80>?
Ignoring exception in command music
Traceback (most recent call last):
  File "C:\Users\ProPCUser\PycharmProjects\lycproject\venv\lib\site-packages\discord\ext\commands\core.py", line 235, in wrapped
    ret = await coro(*args, **kwargs)
  File "C:\Users\ProPCUser\PycharmProjects\lycproject\cogs\music_bot.py", line 105, in music
    embed = await self.quembed_ini(ctx)
  File "C:\Users\ProPCUser\PycharmProjects\lycproject\cogs\music_bot.py", line 78, in quembed_ini
    fields = [(str(self.queue[elem]), get_song_name(elem), False) for elem in list(self.queue.keys())]
  File "C:\Users\ProPCUser\PycharmProjects\lycproject\cogs\music_bot.py", line 78, in <listcomp>
    fields = [(str(self.queue[elem]), get_song_name(elem), False) for elem in list(self.queue.keys())]
  File "C:\Users\ProPCUser\PycharmProjects\lycproject\yt_api.py", line 18, in get_song_name
    r = requests.get(request)
  File "C:\Users\ProPCUser\PycharmProjects\lycproject\venv\lib\site-packages\requests\api.py", line 73, in get
    return request("get", url, params=params, **kwargs)
  File "C:\Users\ProPCUser\PycharmProjects\lycproject\venv\lib\site-packages\requests\api.py", line 59, in request
    return session.request(method=method, url=url, **kwargs)
  File "C:\Users\ProPCUser\PycharmProjects\lycproject\venv\lib\site-packages\requests\sessions.py", line 575, in request
    prep = self.prepare_request(req)
  File "C:\Users\ProPCUser\PycharmProjects\lycproject\venv\lib\site-packages\requests\sessions.py", line 486, in prepare_request
    p.prepare(
  File "C:\Users\ProPCUser\PycharmProjects\lycproject\venv\lib\site-packages\requests\models.py", line 368, in prepare
    self.prepare_url(url, params)
  File "C:\Users\ProPCUser\PycharmProjects\lycproject\venv\lib\site-packages\requests\models.py", line 439, in prepare_url
    raise MissingSchema(
requests.exceptions.MissingSchema: Invalid URL '<cogs.music_bot.YtSource object at 0x0000022469820310>': No scheme supplied. Perhaps you meant https://<cogs.music_bot.YtSource object at 0x0000022469820310>?

The above exception was the direct cause of the following exception:

Traceback (most recent call last):
  File "C:\Users\ProPCUser\PycharmProjects\lycproject\venv\lib\site-packages\discord\ext\commands\bot.py", line 1350, in invoke
    await ctx.command.invoke(ctx)
  File "C:\Users\ProPCUser\PycharmProjects\lycproject\venv\lib\site-packages\discord\ext\commands\core.py", line 1029, in invoke
    await injected(*ctx.args, **ctx.kwargs)  # type: ignore
  File "C:\Users\ProPCUser\PycharmProjects\lycproject\venv\lib\site-packages\discord\ext\commands\core.py", line 244, in wrapped
    raise CommandInvokeError(exc) from exc
discord.ext.commands.errors.CommandInvokeError: Command raised an exception: MissingSchema: Invalid URL '<cogs.music_bot.YtSource object at 0x0000022469820310>': No scheme supplied. Perhaps you meant https://<cogs.music_bot.YtSource object at 0x0000022469820310>?
Ignoring exception in command add_queue
Traceback (most recent call last):
  File "C:\Users\ProPCUser\PycharmProjects\lycproject\venv\lib\site-packages\discord\ext\commands\core.py", line 235, in wrapped
    ret = await coro(*args, **kwargs)
  File "C:\Users\ProPCUser\PycharmProjects\lycproject\cogs\music_bot.py", line 128, in add_queue
    embed = await self.quembed_ini(ctx)
  File "C:\Users\ProPCUser\PycharmProjects\lycproject\cogs\music_bot.py", line 78, in quembed_ini
    fields = [(str(self.queue[elem]), get_song_name(elem), False) for elem in list(self.queue.keys())]
  File "C:\Users\ProPCUser\PycharmProjects\lycproject\cogs\music_bot.py", line 78, in <listcomp>
    fields = [(str(self.queue[elem]), get_song_name(elem), False) for elem in list(self.queue.keys())]
  File "C:\Users\ProPCUser\PycharmProjects\lycproject\yt_api.py", line 18, in get_song_name
    r = requests.get(request)
  File "C:\Users\ProPCUser\PycharmProjects\lycproject\venv\lib\site-packages\requests\api.py", line 73, in get
    return request("get", url, params=params, **kwargs)
  File "C:\Users\ProPCUser\PycharmProjects\lycproject\venv\lib\site-packages\requests\api.py", line 59, in request
    return session.request(method=method, url=url, **kwargs)
  File "C:\Users\ProPCUser\PycharmProjects\lycproject\venv\lib\site-packages\requests\sessions.py", line 575, in request
    prep = self.prepare_request(req)
  File "C:\Users\ProPCUser\PycharmProjects\lycproject\venv\lib\site-packages\requests\sessions.py", line 486, in prepare_request
    p.prepare(
  File "C:\Users\ProPCUser\PycharmProjects\lycproject\venv\lib\site-packages\requests\models.py", line 368, in prepare
    self.prepare_url(url, params)
  File "C:\Users\ProPCUser\PycharmProjects\lycproject\venv\lib\site-packages\requests\models.py", line 439, in prepare_url
    raise MissingSchema(
requests.exceptions.MissingSchema: Invalid URL '<cogs.music_bot.YtSource object at 0x0000022469820310>': No scheme supplied. Perhaps you meant https://<cogs.music_bot.YtSource object at 0x0000022469820310>?

The above exception was the direct cause of the following exception:

Traceback (most recent call last):
  File "C:\Users\ProPCUser\PycharmProjects\lycproject\venv\lib\site-packages\discord\ext\commands\bot.py", line 1350, in invoke
    await ctx.command.invoke(ctx)
  File "C:\Users\ProPCUser\PycharmProjects\lycproject\venv\lib\site-packages\discord\ext\commands\core.py", line 1029, in invoke
    await injected(*ctx.args, **ctx.kwargs)  # type: ignore
  File "C:\Users\ProPCUser\PycharmProjects\lycproject\venv\lib\site-packages\discord\ext\commands\core.py", line 244, in wrapped
    raise CommandInvokeError(exc) from exc
discord.ext.commands.errors.CommandInvokeError: Command raised an exception: MissingSchema: Invalid URL '<cogs.music_bot.YtSource object at 0x0000022469820310>': No scheme supplied. Perhaps you meant https://<cogs.music_bot.YtSource object at 0x0000022469820310>?
Ignoring exception in command music
Traceback (most recent call last):
  File "C:\Users\ProPCUser\PycharmProjects\lycproject\venv\lib\site-packages\discord\ext\commands\core.py", line 235, in wrapped
    ret = await coro(*args, **kwargs)
  File "C:\Users\ProPCUser\PycharmProjects\lycproject\cogs\music_bot.py", line 105, in music
    embed = await self.quembed_ini(ctx)
  File "C:\Users\ProPCUser\PycharmProjects\lycproject\cogs\music_bot.py", line 78, in quembed_ini
    fields = [(str(self.queue[elem]), get_song_name(elem), False) for elem in list(self.queue.keys())]
  File "C:\Users\ProPCUser\PycharmProjects\lycproject\cogs\music_bot.py", line 78, in <listcomp>
    fields = [(str(self.queue[elem]), get_song_name(elem), False) for elem in list(self.queue.keys())]
  File "C:\Users\ProPCUser\PycharmProjects\lycproject\yt_api.py", line 18, in get_song_name
    r = requests.get(request)
  File "C:\Users\ProPCUser\PycharmProjects\lycproject\venv\lib\site-packages\requests\api.py", line 73, in get
    return request("get", url, params=params, **kwargs)
  File "C:\Users\ProPCUser\PycharmProjects\lycproject\venv\lib\site-packages\requests\api.py", line 59, in request
    return session.request(method=method, url=url, **kwargs)
  File "C:\Users\ProPCUser\PycharmProjects\lycproject\venv\lib\site-packages\requests\sessions.py", line 575, in request
    prep = self.prepare_request(req)
  File "C:\Users\ProPCUser\PycharmProjects\lycproject\venv\lib\site-packages\requests\sessions.py", line 486, in prepare_request
    p.prepare(
  File "C:\Users\ProPCUser\PycharmProjects\lycproject\venv\lib\site-packages\requests\models.py", line 368, in prepare
    self.prepare_url(url, params)
  File "C:\Users\ProPCUser\PycharmProjects\lycproject\venv\lib\site-packages\requests\models.py", line 439, in prepare_url
    raise MissingSchema(
requests.exceptions.MissingSchema: Invalid URL '<cogs.music_bot.YtSource object at 0x0000029B0529F820>': No scheme supplied. Perhaps you meant https://<cogs.music_bot.YtSource object at 0x0000029B0529F820>?

The above exception was the direct cause of the following exception:

Traceback (most recent call last):
  File "C:\Users\ProPCUser\PycharmProjects\lycproject\venv\lib\site-packages\discord\ext\commands\bot.py", line 1350, in invoke
    await ctx.command.invoke(ctx)
  File "C:\Users\ProPCUser\PycharmProjects\lycproject\venv\lib\site-packages\discord\ext\commands\core.py", line 1029, in invoke
    await injected(*ctx.args, **ctx.kwargs)  # type: ignore
  File "C:\Users\ProPCUser\PycharmProjects\lycproject\venv\lib\site-packages\discord\ext\commands\core.py", line 244, in wrapped
    raise CommandInvokeError(exc) from exc
discord.ext.commands.errors.CommandInvokeError: Command raised an exception: MissingSchema: Invalid URL '<cogs.music_bot.YtSource object at 0x0000029B0529F820>': No scheme supplied. Perhaps you meant https://<cogs.music_bot.YtSource object at 0x0000029B0529F820>?
Ignoring exception in command add_queue
Traceback (most recent call last):
  File "C:\Users\ProPCUser\PycharmProjects\lycproject\venv\lib\site-packages\discord\ext\commands\core.py", line 235, in wrapped
    ret = await coro(*args, **kwargs)
  File "C:\Users\ProPCUser\PycharmProjects\lycproject\cogs\music_bot.py", line 128, in add_queue
    embed = await self.quembed_ini(ctx)
  File "C:\Users\ProPCUser\PycharmProjects\lycproject\cogs\music_bot.py", line 78, in quembed_ini
    fields = [(str(self.queue[elem]), get_song_name(elem), False) for elem in list(self.queue.keys())]
  File "C:\Users\ProPCUser\PycharmProjects\lycproject\cogs\music_bot.py", line 78, in <listcomp>
    fields = [(str(self.queue[elem]), get_song_name(elem), False) for elem in list(self.queue.keys())]
  File "C:\Users\ProPCUser\PycharmProjects\lycproject\yt_api.py", line 18, in get_song_name
    r = requests.get(request)
  File "C:\Users\ProPCUser\PycharmProjects\lycproject\venv\lib\site-packages\requests\api.py", line 73, in get
    return request("get", url, params=params, **kwargs)
  File "C:\Users\ProPCUser\PycharmProjects\lycproject\venv\lib\site-packages\requests\api.py", line 59, in request
    return session.request(method=method, url=url, **kwargs)
  File "C:\Users\ProPCUser\PycharmProjects\lycproject\venv\lib\site-packages\requests\sessions.py", line 575, in request
    prep = self.prepare_request(req)
  File "C:\Users\ProPCUser\PycharmProjects\lycproject\venv\lib\site-packages\requests\sessions.py", line 486, in prepare_request
    p.prepare(
  File "C:\Users\ProPCUser\PycharmProjects\lycproject\venv\lib\site-packages\requests\models.py", line 368, in prepare
    self.prepare_url(url, params)
  File "C:\Users\ProPCUser\PycharmProjects\lycproject\venv\lib\site-packages\requests\models.py", line 439, in prepare_url
    raise MissingSchema(
requests.exceptions.MissingSchema: Invalid URL '<cogs.music_bot.YtSource object at 0x0000029B0529F820>': No scheme supplied. Perhaps you meant https://<cogs.music_bot.YtSource object at 0x0000029B0529F820>?

The above exception was the direct cause of the following exception:

Traceback (most recent call last):
  File "C:\Users\ProPCUser\PycharmProjects\lycproject\venv\lib\site-packages\discord\ext\commands\bot.py", line 1350, in invoke
    await ctx.command.invoke(ctx)
  File "C:\Users\ProPCUser\PycharmProjects\lycproject\venv\lib\site-packages\discord\ext\commands\core.py", line 1029, in invoke
    await injected(*ctx.args, **ctx.kwargs)  # type: ignore
  File "C:\Users\ProPCUser\PycharmProjects\lycproject\venv\lib\site-packages\discord\ext\commands\core.py", line 244, in wrapped
    raise CommandInvokeError(exc) from exc
discord.ext.commands.errors.CommandInvokeError: Command raised an exception: MissingSchema: Invalid URL '<cogs.music_bot.YtSource object at 0x0000029B0529F820>': No scheme supplied. Perhaps you meant https://<cogs.music_bot.YtSource object at 0x0000029B0529F820>?
Ignoring exception in command music
Traceback (most recent call last):
  File "C:\Users\ProPCUser\PycharmProjects\lycproject\venv\lib\site-packages\discord\ext\commands\core.py", line 235, in wrapped
    ret = await coro(*args, **kwargs)
  File "C:\Users\ProPCUser\PycharmProjects\lycproject\cogs\music_bot.py", line 106, in music
    embed = await self.quembed_ini(ctx)
  File "C:\Users\ProPCUser\PycharmProjects\lycproject\cogs\music_bot.py", line 79, in quembed_ini
    fields = [(str(self.queue[elem]), get_song_name(elem), False) for elem in list(self.queue.keys())]
  File "C:\Users\ProPCUser\PycharmProjects\lycproject\cogs\music_bot.py", line 79, in <listcomp>
    fields = [(str(self.queue[elem]), get_song_name(elem), False) for elem in list(self.queue.keys())]
  File "C:\Users\ProPCUser\PycharmProjects\lycproject\yt_api.py", line 18, in get_song_name
    r = requests.get(request)
  File "C:\Users\ProPCUser\PycharmProjects\lycproject\venv\lib\site-packages\requests\api.py", line 73, in get
    return request("get", url, params=params, **kwargs)
  File "C:\Users\ProPCUser\PycharmProjects\lycproject\venv\lib\site-packages\requests\api.py", line 59, in request
    return session.request(method=method, url=url, **kwargs)
  File "C:\Users\ProPCUser\PycharmProjects\lycproject\venv\lib\site-packages\requests\sessions.py", line 575, in request
    prep = self.prepare_request(req)
  File "C:\Users\ProPCUser\PycharmProjects\lycproject\venv\lib\site-packages\requests\sessions.py", line 486, in prepare_request
    p.prepare(
  File "C:\Users\ProPCUser\PycharmProjects\lycproject\venv\lib\site-packages\requests\models.py", line 368, in prepare
    self.prepare_url(url, params)
  File "C:\Users\ProPCUser\PycharmProjects\lycproject\venv\lib\site-packages\requests\models.py", line 439, in prepare_url
    raise MissingSchema(
requests.exceptions.MissingSchema: Invalid URL '<cogs.music_bot.YtSource object at 0x0000020ECEFDF400>': No scheme supplied. Perhaps you meant https://<cogs.music_bot.YtSource object at 0x0000020ECEFDF400>?

The above exception was the direct cause of the following exception:

Traceback (most recent call last):
  File "C:\Users\ProPCUser\PycharmProjects\lycproject\venv\lib\site-packages\discord\ext\commands\bot.py", line 1350, in invoke
    await ctx.command.invoke(ctx)
  File "C:\Users\ProPCUser\PycharmProjects\lycproject\venv\lib\site-packages\discord\ext\commands\core.py", line 1029, in invoke
    await injected(*ctx.args, **ctx.kwargs)  # type: ignore
  File "C:\Users\ProPCUser\PycharmProjects\lycproject\venv\lib\site-packages\discord\ext\commands\core.py", line 244, in wrapped
    raise CommandInvokeError(exc) from exc
discord.ext.commands.errors.CommandInvokeError: Command raised an exception: MissingSchema: Invalid URL '<cogs.music_bot.YtSource object at 0x0000020ECEFDF400>': No scheme supplied. Perhaps you meant https://<cogs.music_bot.YtSource object at 0x0000020ECEFDF400>?
Ignoring exception in command music
Traceback (most recent call last):
  File "C:\Users\ProPCUser\PycharmProjects\lycproject\venv\lib\site-packages\discord\ext\commands\core.py", line 235, in wrapped
    ret = await coro(*args, **kwargs)
  File "C:\Users\ProPCUser\PycharmProjects\lycproject\cogs\music_bot.py", line 107, in music
    embed = await self.quembed_ini(ctx)
  File "C:\Users\ProPCUser\PycharmProjects\lycproject\cogs\music_bot.py", line 77, in quembed_ini
    fields.append(get_song_name(elem.url), (str(self.queue[elem]), False))
TypeError: append() takes exactly one argument (2 given)

The above exception was the direct cause of the following exception:

Traceback (most recent call last):
  File "C:\Users\ProPCUser\PycharmProjects\lycproject\venv\lib\site-packages\discord\ext\commands\bot.py", line 1350, in invoke
    await ctx.command.invoke(ctx)
  File "C:\Users\ProPCUser\PycharmProjects\lycproject\venv\lib\site-packages\discord\ext\commands\core.py", line 1029, in invoke
    await injected(*ctx.args, **ctx.kwargs)  # type: ignore
  File "C:\Users\ProPCUser\PycharmProjects\lycproject\venv\lib\site-packages\discord\ext\commands\core.py", line 244, in wrapped
    raise CommandInvokeError(exc) from exc
discord.ext.commands.errors.CommandInvokeError: Command raised an exception: TypeError: append() takes exactly one argument (2 given)
Ignoring exception in command music
Traceback (most recent call last):
  File "C:\Users\ProPCUser\PycharmProjects\lycproject\venv\lib\site-packages\discord\ext\commands\core.py", line 235, in wrapped
    ret = await coro(*args, **kwargs)
  File "C:\Users\ProPCUser\PycharmProjects\lycproject\cogs\music_bot.py", line 107, in music
    embed = await self.quembed_ini(ctx)
  File "C:\Users\ProPCUser\PycharmProjects\lycproject\cogs\music_bot.py", line 84, in quembed_ini
    for name, value, inline in fields:
ValueError: not enough values to unpack (expected 3, got 2)

The above exception was the direct cause of the following exception:

Traceback (most recent call last):
  File "C:\Users\ProPCUser\PycharmProjects\lycproject\venv\lib\site-packages\discord\ext\commands\bot.py", line 1350, in invoke
    await ctx.command.invoke(ctx)
  File "C:\Users\ProPCUser\PycharmProjects\lycproject\venv\lib\site-packages\discord\ext\commands\core.py", line 1029, in invoke
    await injected(*ctx.args, **ctx.kwargs)  # type: ignore
  File "C:\Users\ProPCUser\PycharmProjects\lycproject\venv\lib\site-packages\discord\ext\commands\core.py", line 244, in wrapped
    raise CommandInvokeError(exc) from exc
discord.ext.commands.errors.CommandInvokeError: Command raised an exception: ValueError: not enough values to unpack (expected 3, got 2)
Ignoring exception in command add_queue
Traceback (most recent call last):
  File "C:\Users\ProPCUser\PycharmProjects\lycproject\venv\lib\site-packages\discord\ext\commands\core.py", line 235, in wrapped
    ret = await coro(*args, **kwargs)
  File "C:\Users\ProPCUser\PycharmProjects\lycproject\cogs\music_bot.py", line 130, in add_queue
    embed = await self.quembed_ini(ctx)
  File "C:\Users\ProPCUser\PycharmProjects\lycproject\cogs\music_bot.py", line 84, in quembed_ini
    for name, value, inline in fields:
ValueError: not enough values to unpack (expected 3, got 2)

The above exception was the direct cause of the following exception:

Traceback (most recent call last):
  File "C:\Users\ProPCUser\PycharmProjects\lycproject\venv\lib\site-packages\discord\ext\commands\bot.py", line 1350, in invoke
    await ctx.command.invoke(ctx)
  File "C:\Users\ProPCUser\PycharmProjects\lycproject\venv\lib\site-packages\discord\ext\commands\core.py", line 1029, in invoke
    await injected(*ctx.args, **ctx.kwargs)  # type: ignore
  File "C:\Users\ProPCUser\PycharmProjects\lycproject\venv\lib\site-packages\discord\ext\commands\core.py", line 244, in wrapped
    raise CommandInvokeError(exc) from exc
discord.ext.commands.errors.CommandInvokeError: Command raised an exception: ValueError: not enough values to unpack (expected 3, got 2)
Ignoring exception in command add_queue
Traceback (most recent call last):
  File "C:\Users\ProPCUser\PycharmProjects\lycproject\venv\lib\site-packages\discord\ext\commands\core.py", line 235, in wrapped
    ret = await coro(*args, **kwargs)
  File "C:\Users\ProPCUser\PycharmProjects\lycproject\cogs\music_bot.py", line 136, in add_queue
    embed = await self.quembed_ini(ctx)
  File "C:\Users\ProPCUser\PycharmProjects\lycproject\cogs\music_bot.py", line 71, in quembed_ini
    if vc.is_playing():
AttributeError: 'NoneType' object has no attribute 'is_playing'

The above exception was the direct cause of the following exception:

Traceback (most recent call last):
  File "C:\Users\ProPCUser\PycharmProjects\lycproject\venv\lib\site-packages\discord\ext\commands\bot.py", line 1350, in invoke
    await ctx.command.invoke(ctx)
  File "C:\Users\ProPCUser\PycharmProjects\lycproject\venv\lib\site-packages\discord\ext\commands\core.py", line 1029, in invoke
    await injected(*ctx.args, **ctx.kwargs)  # type: ignore
  File "C:\Users\ProPCUser\PycharmProjects\lycproject\venv\lib\site-packages\discord\ext\commands\core.py", line 244, in wrapped
    raise CommandInvokeError(exc) from exc
discord.ext.commands.errors.CommandInvokeError: Command raised an exception: AttributeError: 'NoneType' object has no attribute 'is_playing'
Ignoring exception in command music
Traceback (most recent call last):
  File "C:\Users\ProPCUser\PycharmProjects\lycproject\venv\lib\site-packages\discord\ext\commands\core.py", line 235, in wrapped
    ret = await coro(*args, **kwargs)
  File "C:\Users\ProPCUser\PycharmProjects\lycproject\cogs\music_bot.py", line 101, in music
    if get(self.bot.voice_clients, guild=ctx.guild).is_playing():
AttributeError: 'NoneType' object has no attribute 'is_playing'

The above exception was the direct cause of the following exception:

Traceback (most recent call last):
  File "C:\Users\ProPCUser\PycharmProjects\lycproject\venv\lib\site-packages\discord\ext\commands\bot.py", line 1350, in invoke
    await ctx.command.invoke(ctx)
  File "C:\Users\ProPCUser\PycharmProjects\lycproject\venv\lib\site-packages\discord\ext\commands\core.py", line 1029, in invoke
    await injected(*ctx.args, **ctx.kwargs)  # type: ignore
  File "C:\Users\ProPCUser\PycharmProjects\lycproject\venv\lib\site-packages\discord\ext\commands\core.py", line 244, in wrapped
    raise CommandInvokeError(exc) from exc
discord.ext.commands.errors.CommandInvokeError: Command raised an exception: AttributeError: 'NoneType' object has no attribute 'is_playing'
Ignoring exception in command add_queue
Traceback (most recent call last):
  File "C:\Users\ProPCUser\PycharmProjects\lycproject\venv\lib\site-packages\discord\ext\commands\core.py", line 235, in wrapped
    ret = await coro(*args, **kwargs)
  File "C:\Users\ProPCUser\PycharmProjects\lycproject\cogs\music_bot.py", line 129, in add_queue
    await self.music(ctx, url)
  File "C:\Users\ProPCUser\PycharmProjects\lycproject\venv\lib\site-packages\discord\ext\commands\core.py", line 588, in __call__
    return await self.callback(self.cog, context, *args, **kwargs)  # type: ignore
  File "C:\Users\ProPCUser\PycharmProjects\lycproject\cogs\music_bot.py", line 96, in music
    if get(self.bot.voice_clients, guild=ctx.guild).is_playing():
AttributeError: 'NoneType' object has no attribute 'is_playing'

The above exception was the direct cause of the following exception:

Traceback (most recent call last):
  File "C:\Users\ProPCUser\PycharmProjects\lycproject\venv\lib\site-packages\discord\ext\commands\bot.py", line 1350, in invoke
    await ctx.command.invoke(ctx)
  File "C:\Users\ProPCUser\PycharmProjects\lycproject\venv\lib\site-packages\discord\ext\commands\core.py", line 1029, in invoke
    await injected(*ctx.args, **ctx.kwargs)  # type: ignore
  File "C:\Users\ProPCUser\PycharmProjects\lycproject\venv\lib\site-packages\discord\ext\commands\core.py", line 244, in wrapped
    raise CommandInvokeError(exc) from exc
discord.ext.commands.errors.CommandInvokeError: Command raised an exception: AttributeError: 'NoneType' object has no attribute 'is_playing'
Ignoring exception in command add_queue
Traceback (most recent call last):
  File "C:\Users\ProPCUser\PycharmProjects\lycproject\venv\lib\site-packages\discord\ext\commands\core.py", line 235, in wrapped
    ret = await coro(*args, **kwargs)
  File "C:\Users\ProPCUser\PycharmProjects\lycproject\cogs\music_bot.py", line 132, in add_queue
    await self.music(ctx, url)
  File "C:\Users\ProPCUser\PycharmProjects\lycproject\venv\lib\site-packages\discord\ext\commands\core.py", line 588, in __call__
    return await self.callback(self.cog, context, *args, **kwargs)  # type: ignore
  File "C:\Users\ProPCUser\PycharmProjects\lycproject\cogs\music_bot.py", line 99, in music
    if get(self.bot.voice_clients, guild=ctx.guild).is_playing():
AttributeError: 'NoneType' object has no attribute 'is_playing'

The above exception was the direct cause of the following exception:

Traceback (most recent call last):
  File "C:\Users\ProPCUser\PycharmProjects\lycproject\venv\lib\site-packages\discord\ext\commands\bot.py", line 1350, in invoke
    await ctx.command.invoke(ctx)
  File "C:\Users\ProPCUser\PycharmProjects\lycproject\venv\lib\site-packages\discord\ext\commands\core.py", line 1029, in invoke
    await injected(*ctx.args, **ctx.kwargs)  # type: ignore
  File "C:\Users\ProPCUser\PycharmProjects\lycproject\venv\lib\site-packages\discord\ext\commands\core.py", line 244, in wrapped
    raise CommandInvokeError(exc) from exc
discord.ext.commands.errors.CommandInvokeError: Command raised an exception: AttributeError: 'NoneType' object has no attribute 'is_playing'
Ignoring exception in command music
Traceback (most recent call last):
  File "C:\Users\ProPCUser\PycharmProjects\lycproject\venv\lib\site-packages\discord\ext\commands\core.py", line 235, in wrapped
    ret = await coro(*args, **kwargs)
  File "C:\Users\ProPCUser\PycharmProjects\lycproject\cogs\music_bot.py", line 94, in music
    await self.music_cleanup(ctx, player=await YtSource.create_source(ctx, url, loop=self.bot.loop))
  File "C:\Users\ProPCUser\PycharmProjects\lycproject\cogs\music_bot.py", line 104, in music_cleanup
    embed = await self.quembed_ini(ctx, status="Играет")
  File "C:\Users\ProPCUser\PycharmProjects\lycproject\cogs\music_bot.py", line 73, in quembed_ini
    fields.append((elem.title, elem.url), False)
TypeError: append() takes exactly one argument (2 given)

The above exception was the direct cause of the following exception:

Traceback (most recent call last):
  File "C:\Users\ProPCUser\PycharmProjects\lycproject\venv\lib\site-packages\discord\ext\commands\bot.py", line 1350, in invoke
    await ctx.command.invoke(ctx)
  File "C:\Users\ProPCUser\PycharmProjects\lycproject\venv\lib\site-packages\discord\ext\commands\core.py", line 1029, in invoke
    await injected(*ctx.args, **ctx.kwargs)  # type: ignore
  File "C:\Users\ProPCUser\PycharmProjects\lycproject\venv\lib\site-packages\discord\ext\commands\core.py", line 244, in wrapped
    raise CommandInvokeError(exc) from exc
discord.ext.commands.errors.CommandInvokeError: Command raised an exception: TypeError: append() takes exactly one argument (2 given)
Ignoring exception in command music
Traceback (most recent call last):
  File "C:\Users\ProPCUser\PycharmProjects\lycproject\venv\lib\site-packages\discord\ext\commands\core.py", line 235, in wrapped
    ret = await coro(*args, **kwargs)
  File "C:\Users\ProPCUser\PycharmProjects\lycproject\cogs\music_bot.py", line 88, in music
    await self.add_queue(ctx, url)
  File "C:\Users\ProPCUser\PycharmProjects\lycproject\venv\lib\site-packages\discord\ext\commands\core.py", line 588, in __call__
    return await self.callback(self.cog, context, *args, **kwargs)  # type: ignore
  File "C:\Users\ProPCUser\PycharmProjects\lycproject\cogs\music_bot.py", line 132, in add_queue
    await self._await.put(await self.start_playing(ctx, ctx.voice_client))
  File "C:\Users\ProPCUser\PycharmProjects\lycproject\cogs\music_bot.py", line 123, in start_playing
    voice_client.play(self.queue[0], after=lambda _: self.bot.loop.call_soon_threadsafe(self.next.set))
IndexError: list index out of range

The above exception was the direct cause of the following exception:

Traceback (most recent call last):
  File "C:\Users\ProPCUser\PycharmProjects\lycproject\venv\lib\site-packages\discord\ext\commands\bot.py", line 1350, in invoke
    await ctx.command.invoke(ctx)
  File "C:\Users\ProPCUser\PycharmProjects\lycproject\venv\lib\site-packages\discord\ext\commands\core.py", line 1029, in invoke
    await injected(*ctx.args, **ctx.kwargs)  # type: ignore
  File "C:\Users\ProPCUser\PycharmProjects\lycproject\venv\lib\site-packages\discord\ext\commands\core.py", line 244, in wrapped
    raise CommandInvokeError(exc) from exc
discord.ext.commands.errors.CommandInvokeError: Command raised an exception: IndexError: list index out of range
Ignoring exception in command add_queue
Traceback (most recent call last):
  File "C:\Users\ProPCUser\PycharmProjects\lycproject\venv\lib\site-packages\discord\ext\commands\core.py", line 235, in wrapped
    ret = await coro(*args, **kwargs)
  File "C:\Users\ProPCUser\PycharmProjects\lycproject\cogs\music_bot.py", line 134, in add_queue
    await self._await.put(await self.start_playing(ctx, ctx.voice_client))
  File "C:\Users\ProPCUser\PycharmProjects\lycproject\cogs\music_bot.py", line 123, in start_playing
    voice_client.play(self.queue[0], after=lambda _: self.bot.loop.call_soon_threadsafe(self.next.set))
  File "C:\Users\ProPCUser\PycharmProjects\lycproject\venv\lib\site-packages\discord\voice_client.py", line 608, in play
    raise ClientException('Already playing audio.')
discord.errors.ClientException: Already playing audio.

The above exception was the direct cause of the following exception:

Traceback (most recent call last):
  File "C:\Users\ProPCUser\PycharmProjects\lycproject\venv\lib\site-packages\discord\ext\commands\bot.py", line 1350, in invoke
    await ctx.command.invoke(ctx)
  File "C:\Users\ProPCUser\PycharmProjects\lycproject\venv\lib\site-packages\discord\ext\commands\core.py", line 1029, in invoke
    await injected(*ctx.args, **ctx.kwargs)  # type: ignore
  File "C:\Users\ProPCUser\PycharmProjects\lycproject\venv\lib\site-packages\discord\ext\commands\core.py", line 244, in wrapped
    raise CommandInvokeError(exc) from exc
discord.ext.commands.errors.CommandInvokeError: Command raised an exception: ClientException: Already playing audio.
Ignoring exception in command add_queue
Traceback (most recent call last):
  File "C:\Users\ProPCUser\PycharmProjects\lycproject\venv\lib\site-packages\discord\ext\commands\core.py", line 235, in wrapped
    ret = await coro(*args, **kwargs)
  File "C:\Users\ProPCUser\PycharmProjects\lycproject\cogs\music_bot.py", line 136, in add_queue
    await self._await.put(await self.start_playing(ctx, ctx.voice_client))
  File "C:\Users\ProPCUser\PycharmProjects\lycproject\cogs\music_bot.py", line 123, in start_playing
    voice_client.play(self.queue[0], after=lambda _: self.bot.loop.call_soon_threadsafe(self.next.set))
  File "C:\Users\ProPCUser\PycharmProjects\lycproject\venv\lib\site-packages\discord\voice_client.py", line 608, in play
    raise ClientException('Already playing audio.')
discord.errors.ClientException: Already playing audio.

The above exception was the direct cause of the following exception:

Traceback (most recent call last):
  File "C:\Users\ProPCUser\PycharmProjects\lycproject\venv\lib\site-packages\discord\ext\commands\bot.py", line 1350, in invoke
    await ctx.command.invoke(ctx)
  File "C:\Users\ProPCUser\PycharmProjects\lycproject\venv\lib\site-packages\discord\ext\commands\core.py", line 1029, in invoke
    await injected(*ctx.args, **ctx.kwargs)  # type: ignore
  File "C:\Users\ProPCUser\PycharmProjects\lycproject\venv\lib\site-packages\discord\ext\commands\core.py", line 244, in wrapped
    raise CommandInvokeError(exc) from exc
discord.ext.commands.errors.CommandInvokeError: Command raised an exception: ClientException: Already playing audio.
Ignoring exception in command music
Traceback (most recent call last):
  File "C:\Users\ProPCUser\PycharmProjects\lycproject\venv\lib\site-packages\discord\ext\commands\core.py", line 235, in wrapped
    ret = await coro(*args, **kwargs)
  File "C:\Users\ProPCUser\PycharmProjects\lycproject\cogs\music_bot.py", line 88, in music
    await self.add_queue(ctx, url)
  File "C:\Users\ProPCUser\PycharmProjects\lycproject\venv\lib\site-packages\discord\ext\commands\core.py", line 588, in __call__
    return await self.callback(self.cog, context, *args, **kwargs)  # type: ignore
  File "C:\Users\ProPCUser\PycharmProjects\lycproject\cogs\music_bot.py", line 134, in add_queue
    await ctx.voice_client.play(self.queue[0], after=lambda _: self.bot.loop.call_soon_threadsafe(self.next.set))
TypeError: object NoneType can't be used in 'await' expression

The above exception was the direct cause of the following exception:

Traceback (most recent call last):
  File "C:\Users\ProPCUser\PycharmProjects\lycproject\venv\lib\site-packages\discord\ext\commands\bot.py", line 1350, in invoke
    await ctx.command.invoke(ctx)
  File "C:\Users\ProPCUser\PycharmProjects\lycproject\venv\lib\site-packages\discord\ext\commands\core.py", line 1029, in invoke
    await injected(*ctx.args, **ctx.kwargs)  # type: ignore
  File "C:\Users\ProPCUser\PycharmProjects\lycproject\venv\lib\site-packages\discord\ext\commands\core.py", line 244, in wrapped
    raise CommandInvokeError(exc) from exc
discord.ext.commands.errors.CommandInvokeError: Command raised an exception: TypeError: object NoneType can't be used in 'await' expression
Ignoring exception in command add_queue
Traceback (most recent call last):
  File "C:\Users\ProPCUser\PycharmProjects\lycproject\venv\lib\site-packages\discord\ext\commands\core.py", line 235, in wrapped
    ret = await coro(*args, **kwargs)
  File "C:\Users\ProPCUser\PycharmProjects\lycproject\cogs\music_bot.py", line 134, in add_queue
    await ctx.voice_client.play(self.queue[0], after=lambda _: self.bot.loop.call_soon_threadsafe(self.next.set))
  File "C:\Users\ProPCUser\PycharmProjects\lycproject\venv\lib\site-packages\discord\voice_client.py", line 608, in play
    raise ClientException('Already playing audio.')
discord.errors.ClientException: Already playing audio.

The above exception was the direct cause of the following exception:

Traceback (most recent call last):
  File "C:\Users\ProPCUser\PycharmProjects\lycproject\venv\lib\site-packages\discord\ext\commands\bot.py", line 1350, in invoke
    await ctx.command.invoke(ctx)
  File "C:\Users\ProPCUser\PycharmProjects\lycproject\venv\lib\site-packages\discord\ext\commands\core.py", line 1029, in invoke
    await injected(*ctx.args, **ctx.kwargs)  # type: ignore
  File "C:\Users\ProPCUser\PycharmProjects\lycproject\venv\lib\site-packages\discord\ext\commands\core.py", line 244, in wrapped
    raise CommandInvokeError(exc) from exc
discord.ext.commands.errors.CommandInvokeError: Command raised an exception: ClientException: Already playing audio.
Ignoring exception in command add_queue
Traceback (most recent call last):
  File "C:\Users\ProPCUser\PycharmProjects\lycproject\venv\lib\site-packages\discord\ext\commands\core.py", line 235, in wrapped
    ret = await coro(*args, **kwargs)
  File "C:\Users\ProPCUser\PycharmProjects\lycproject\cogs\music_bot.py", line 136, in add_queue
    await self._await.put(await self.start_playing(ctx, ctx.voice_client))
  File "C:\Users\ProPCUser\PycharmProjects\lycproject\cogs\music_bot.py", line 123, in start_playing
    voice_client.play(self.queue[0], after=lambda _: self.bot.loop.call_soon_threadsafe(self.next.set))
  File "C:\Users\ProPCUser\PycharmProjects\lycproject\venv\lib\site-packages\discord\voice_client.py", line 608, in play
    raise ClientException('Already playing audio.')
discord.errors.ClientException: Already playing audio.

The above exception was the direct cause of the following exception:

Traceback (most recent call last):
  File "C:\Users\ProPCUser\PycharmProjects\lycproject\venv\lib\site-packages\discord\ext\commands\bot.py", line 1350, in invoke
    await ctx.command.invoke(ctx)
  File "C:\Users\ProPCUser\PycharmProjects\lycproject\venv\lib\site-packages\discord\ext\commands\core.py", line 1029, in invoke
    await injected(*ctx.args, **ctx.kwargs)  # type: ignore
  File "C:\Users\ProPCUser\PycharmProjects\lycproject\venv\lib\site-packages\discord\ext\commands\core.py", line 244, in wrapped
    raise CommandInvokeError(exc) from exc
discord.ext.commands.errors.CommandInvokeError: Command raised an exception: ClientException: Already playing audio.
Ignoring exception in command music
Traceback (most recent call last):
  File "C:\Users\ProPCUser\PycharmProjects\lycproject\venv\lib\site-packages\discord\ext\commands\core.py", line 235, in wrapped
    ret = await coro(*args, **kwargs)
  File "C:\Users\ProPCUser\PycharmProjects\lycproject\cogs\music_bot.py", line 92, in music
    await self.music_cleanup(ctx, player=await YtSource.create_source(ctx, url, loop=self.bot.loop))
  File "C:\Users\ProPCUser\PycharmProjects\lycproject\cogs\music_bot.py", line 102, in music_cleanup
    embed = await self.quembed_ini(ctx, status="Играет")
  File "C:\Users\ProPCUser\PycharmProjects\lycproject\cogs\music_bot.py", line 64, in quembed_ini
    if vc.is_closed():
AttributeError: 'VoiceClient' object has no attribute 'is_closed'

The above exception was the direct cause of the following exception:

Traceback (most recent call last):
  File "C:\Users\ProPCUser\PycharmProjects\lycproject\venv\lib\site-packages\discord\ext\commands\bot.py", line 1350, in invoke
    await ctx.command.invoke(ctx)
  File "C:\Users\ProPCUser\PycharmProjects\lycproject\venv\lib\site-packages\discord\ext\commands\core.py", line 1029, in invoke
    await injected(*ctx.args, **ctx.kwargs)  # type: ignore
  File "C:\Users\ProPCUser\PycharmProjects\lycproject\venv\lib\site-packages\discord\ext\commands\core.py", line 244, in wrapped
    raise CommandInvokeError(exc) from exc
discord.ext.commands.errors.CommandInvokeError: Command raised an exception: AttributeError: 'VoiceClient' object has no attribute 'is_closed'
Ignoring exception in command add_queue
Traceback (most recent call last):
  File "C:\Users\ProPCUser\PycharmProjects\lycproject\venv\lib\site-packages\discord\ext\commands\core.py", line 235, in wrapped
    ret = await coro(*args, **kwargs)
  File "C:\Users\ProPCUser\PycharmProjects\lycproject\cogs\music_bot.py", line 140, in add_queue
    await self._await.put(await self.start_playing(ctx, ctx.voice_client))
  File "C:\Users\ProPCUser\PycharmProjects\lycproject\cogs\music_bot.py", line 127, in start_playing
    voice_client.play(self.queue[0], after=lambda _: self.bot.loop.call_soon_threadsafe(self.next.set))
  File "C:\Users\ProPCUser\PycharmProjects\lycproject\venv\lib\site-packages\discord\voice_client.py", line 608, in play
    raise ClientException('Already playing audio.')
discord.errors.ClientException: Already playing audio.

The above exception was the direct cause of the following exception:

Traceback (most recent call last):
  File "C:\Users\ProPCUser\PycharmProjects\lycproject\venv\lib\site-packages\discord\ext\commands\bot.py", line 1350, in invoke
    await ctx.command.invoke(ctx)
  File "C:\Users\ProPCUser\PycharmProjects\lycproject\venv\lib\site-packages\discord\ext\commands\core.py", line 1029, in invoke
    await injected(*ctx.args, **ctx.kwargs)  # type: ignore
  File "C:\Users\ProPCUser\PycharmProjects\lycproject\venv\lib\site-packages\discord\ext\commands\core.py", line 244, in wrapped
    raise CommandInvokeError(exc) from exc
discord.ext.commands.errors.CommandInvokeError: Command raised an exception: ClientException: Already playing audio.
Ignoring exception in command music
Traceback (most recent call last):
  File "C:\Users\ProPCUser\PycharmProjects\lycproject\venv\lib\site-packages\discord\ext\commands\core.py", line 235, in wrapped
    ret = await coro(*args, **kwargs)
  File "C:\Users\ProPCUser\PycharmProjects\lycproject\cogs\music_bot.py", line 88, in music
    await self.add_queue(ctx, url)
  File "C:\Users\ProPCUser\PycharmProjects\lycproject\venv\lib\site-packages\discord\ext\commands\core.py", line 588, in __call__
    return await self.callback(self.cog, context, *args, **kwargs)  # type: ignore
  File "C:\Users\ProPCUser\PycharmProjects\lycproject\cogs\music_bot.py", line 141, in add_queue
    await self._await.put(await self.start_playing(ctx, ctx.voice_client))
  File "C:\Users\ProPCUser\PycharmProjects\lycproject\cogs\music_bot.py", line 128, in start_playing
    await voice_client.play(self.queue[0], after=lambda _: self.bot.loop.call_soon_threadsafe(self.next.set))
TypeError: object NoneType can't be used in 'await' expression

The above exception was the direct cause of the following exception:

Traceback (most recent call last):
  File "C:\Users\ProPCUser\PycharmProjects\lycproject\venv\lib\site-packages\discord\ext\commands\bot.py", line 1350, in invoke
    await ctx.command.invoke(ctx)
  File "C:\Users\ProPCUser\PycharmProjects\lycproject\venv\lib\site-packages\discord\ext\commands\core.py", line 1029, in invoke
    await injected(*ctx.args, **ctx.kwargs)  # type: ignore
  File "C:\Users\ProPCUser\PycharmProjects\lycproject\venv\lib\site-packages\discord\ext\commands\core.py", line 244, in wrapped
    raise CommandInvokeError(exc) from exc
discord.ext.commands.errors.CommandInvokeError: Command raised an exception: TypeError: object NoneType can't be used in 'await' expression
Ignoring exception in command add_queue
Traceback (most recent call last):
  File "C:\Users\ProPCUser\PycharmProjects\lycproject\venv\lib\site-packages\discord\ext\commands\core.py", line 235, in wrapped
    ret = await coro(*args, **kwargs)
  File "C:\Users\ProPCUser\PycharmProjects\lycproject\cogs\music_bot.py", line 141, in add_queue
    await self._await.put(await self.start_playing(ctx, ctx.voice_client))
  File "C:\Users\ProPCUser\PycharmProjects\lycproject\cogs\music_bot.py", line 128, in start_playing
    await voice_client.play(self.queue[0], after=lambda _: self.bot.loop.call_soon_threadsafe(self.next.set))
  File "C:\Users\ProPCUser\PycharmProjects\lycproject\venv\lib\site-packages\discord\voice_client.py", line 608, in play
    raise ClientException('Already playing audio.')
discord.errors.ClientException: Already playing audio.

The above exception was the direct cause of the following exception:

Traceback (most recent call last):
  File "C:\Users\ProPCUser\PycharmProjects\lycproject\venv\lib\site-packages\discord\ext\commands\bot.py", line 1350, in invoke
    await ctx.command.invoke(ctx)
  File "C:\Users\ProPCUser\PycharmProjects\lycproject\venv\lib\site-packages\discord\ext\commands\core.py", line 1029, in invoke
    await injected(*ctx.args, **ctx.kwargs)  # type: ignore
  File "C:\Users\ProPCUser\PycharmProjects\lycproject\venv\lib\site-packages\discord\ext\commands\core.py", line 244, in wrapped
    raise CommandInvokeError(exc) from exc
discord.ext.commands.errors.CommandInvokeError: Command raised an exception: ClientException: Already playing audio.
Ignoring exception in command add_queue
Traceback (most recent call last):
  File "C:\Users\ProPCUser\PycharmProjects\lycproject\venv\lib\site-packages\discord\ext\commands\core.py", line 235, in wrapped
    ret = await coro(*args, **kwargs)
  File "C:\Users\ProPCUser\PycharmProjects\lycproject\cogs\music_bot.py", line 141, in add_queue
    await self._await.put(await self.start_playing(ctx, ctx.voice_client))
  File "C:\Users\ProPCUser\PycharmProjects\lycproject\cogs\music_bot.py", line 128, in start_playing
    voice_client.play(self.queue[0], after=lambda _: self.bot.loop.call_soon_threadsafe(self.next.set))
  File "C:\Users\ProPCUser\PycharmProjects\lycproject\venv\lib\site-packages\discord\voice_client.py", line 608, in play
    raise ClientException('Already playing audio.')
discord.errors.ClientException: Already playing audio.

The above exception was the direct cause of the following exception:

Traceback (most recent call last):
  File "C:\Users\ProPCUser\PycharmProjects\lycproject\venv\lib\site-packages\discord\ext\commands\bot.py", line 1350, in invoke
    await ctx.command.invoke(ctx)
  File "C:\Users\ProPCUser\PycharmProjects\lycproject\venv\lib\site-packages\discord\ext\commands\core.py", line 1029, in invoke
    await injected(*ctx.args, **ctx.kwargs)  # type: ignore
  File "C:\Users\ProPCUser\PycharmProjects\lycproject\venv\lib\site-packages\discord\ext\commands\core.py", line 244, in wrapped
    raise CommandInvokeError(exc) from exc
discord.ext.commands.errors.CommandInvokeError: Command raised an exception: ClientException: Already playing audio.
Ignoring exception in command add_queue
Traceback (most recent call last):
  File "C:\Users\ProPCUser\PycharmProjects\lycproject\venv\lib\site-packages\discord\ext\commands\core.py", line 235, in wrapped
    ret = await coro(*args, **kwargs)
  File "C:\Users\ProPCUser\PycharmProjects\lycproject\cogs\music_bot.py", line 144, in add_queue
    await self._await.put(await self.start_playing(ctx, ctx.voice_client))
  File "C:\Users\ProPCUser\PycharmProjects\lycproject\cogs\music_bot.py", line 131, in start_playing
    voice_client.play(self.queue[0], after=lambda _: self.bot.loop.call_soon_threadsafe(self.next.set))
  File "C:\Users\ProPCUser\PycharmProjects\lycproject\venv\lib\site-packages\discord\voice_client.py", line 608, in play
    raise ClientException('Already playing audio.')
discord.errors.ClientException: Already playing audio.

The above exception was the direct cause of the following exception:

Traceback (most recent call last):
  File "C:\Users\ProPCUser\PycharmProjects\lycproject\venv\lib\site-packages\discord\ext\commands\bot.py", line 1350, in invoke
    await ctx.command.invoke(ctx)
  File "C:\Users\ProPCUser\PycharmProjects\lycproject\venv\lib\site-packages\discord\ext\commands\core.py", line 1029, in invoke
    await injected(*ctx.args, **ctx.kwargs)  # type: ignore
  File "C:\Users\ProPCUser\PycharmProjects\lycproject\venv\lib\site-packages\discord\ext\commands\core.py", line 244, in wrapped
    raise CommandInvokeError(exc) from exc
discord.ext.commands.errors.CommandInvokeError: Command raised an exception: ClientException: Already playing audio.
Ignoring exception in command add_queue
Traceback (most recent call last):
  File "C:\Users\ProPCUser\PycharmProjects\lycproject\venv\lib\site-packages\discord\ext\commands\core.py", line 235, in wrapped
    ret = await coro(*args, **kwargs)
  File "C:\Users\ProPCUser\PycharmProjects\lycproject\cogs\music_bot.py", line 145, in add_queue
    await self._await.put(await self.start_playing(ctx, ctx.voice_client))
  File "C:\Users\ProPCUser\PycharmProjects\lycproject\cogs\music_bot.py", line 132, in start_playing
    voice_client.play(self.queue[0], after=lambda _: self.bot.loop.call_soon_threadsafe(self.next.set))
  File "C:\Users\ProPCUser\PycharmProjects\lycproject\venv\lib\site-packages\discord\voice_client.py", line 608, in play
    raise ClientException('Already playing audio.')
discord.errors.ClientException: Already playing audio.

The above exception was the direct cause of the following exception:

Traceback (most recent call last):
  File "C:\Users\ProPCUser\PycharmProjects\lycproject\venv\lib\site-packages\discord\ext\commands\bot.py", line 1350, in invoke
    await ctx.command.invoke(ctx)
  File "C:\Users\ProPCUser\PycharmProjects\lycproject\venv\lib\site-packages\discord\ext\commands\core.py", line 1029, in invoke
    await injected(*ctx.args, **ctx.kwargs)  # type: ignore
  File "C:\Users\ProPCUser\PycharmProjects\lycproject\venv\lib\site-packages\discord\ext\commands\core.py", line 244, in wrapped
    raise CommandInvokeError(exc) from exc
discord.ext.commands.errors.CommandInvokeError: Command raised an exception: ClientException: Already playing audio.
Ignoring exception in command add_queue
Traceback (most recent call last):
  File "C:\Users\ProPCUser\PycharmProjects\lycproject\venv\lib\site-packages\discord\ext\commands\core.py", line 235, in wrapped
    ret = await coro(*args, **kwargs)
  File "C:\Users\ProPCUser\PycharmProjects\lycproject\cogs\music_bot.py", line 142, in add_queue
    await self._await.put(await self.start_playing(ctx, ctx.voice_client))
  File "C:\Users\ProPCUser\PycharmProjects\lycproject\cogs\music_bot.py", line 130, in start_playing
    voice_client.play(self.queue[0], after=lambda _: self.bot.loop.call_soon_threadsafe(self.next.set))
  File "C:\Users\ProPCUser\PycharmProjects\lycproject\venv\lib\site-packages\discord\voice_client.py", line 608, in play
    raise ClientException('Already playing audio.')
discord.errors.ClientException: Already playing audio.

The above exception was the direct cause of the following exception:

Traceback (most recent call last):
  File "C:\Users\ProPCUser\PycharmProjects\lycproject\venv\lib\site-packages\discord\ext\commands\bot.py", line 1350, in invoke
    await ctx.command.invoke(ctx)
  File "C:\Users\ProPCUser\PycharmProjects\lycproject\venv\lib\site-packages\discord\ext\commands\core.py", line 1029, in invoke
    await injected(*ctx.args, **ctx.kwargs)  # type: ignore
  File "C:\Users\ProPCUser\PycharmProjects\lycproject\venv\lib\site-packages\discord\ext\commands\core.py", line 244, in wrapped
    raise CommandInvokeError(exc) from exc
discord.ext.commands.errors.CommandInvokeError: Command raised an exception: ClientException: Already playing audio.
Ignoring exception in command add_queue
Traceback (most recent call last):
  File "C:\Users\ProPCUser\PycharmProjects\lycproject\venv\lib\site-packages\discord\ext\commands\core.py", line 235, in wrapped
    ret = await coro(*args, **kwargs)
  File "C:\Users\ProPCUser\PycharmProjects\lycproject\cogs\music_bot.py", line 144, in add_queue
    await self._await.put(await self.start_playing(ctx, ctx.voice_client))
  File "C:\Users\ProPCUser\PycharmProjects\lycproject\cogs\music_bot.py", line 131, in start_playing
    voice_client.play(self.queue[0], after=lambda _: self.bot.loop.call_soon_threadsafe(self.next.set))
  File "C:\Users\ProPCUser\PycharmProjects\lycproject\venv\lib\site-packages\discord\voice_client.py", line 608, in play
    raise ClientException('Already playing audio.')
discord.errors.ClientException: Already playing audio.

The above exception was the direct cause of the following exception:

Traceback (most recent call last):
  File "C:\Users\ProPCUser\PycharmProjects\lycproject\venv\lib\site-packages\discord\ext\commands\bot.py", line 1350, in invoke
    await ctx.command.invoke(ctx)
  File "C:\Users\ProPCUser\PycharmProjects\lycproject\venv\lib\site-packages\discord\ext\commands\core.py", line 1029, in invoke
    await injected(*ctx.args, **ctx.kwargs)  # type: ignore
  File "C:\Users\ProPCUser\PycharmProjects\lycproject\venv\lib\site-packages\discord\ext\commands\core.py", line 244, in wrapped
    raise CommandInvokeError(exc) from exc
discord.ext.commands.errors.CommandInvokeError: Command raised an exception: ClientException: Already playing audio.
Ignoring exception in command add_queue
Traceback (most recent call last):
  File "C:\Users\ProPCUser\PycharmProjects\lycproject\venv\lib\site-packages\discord\ext\commands\core.py", line 235, in wrapped
    ret = await coro(*args, **kwargs)
  File "C:\Users\ProPCUser\PycharmProjects\lycproject\cogs\music_bot.py", line 141, in add_queue
    await self._await.put(await self.start_playing(ctx, ctx.voice_client))
  File "C:\Users\ProPCUser\PycharmProjects\lycproject\cogs\music_bot.py", line 129, in start_playing
    voice_client.play(self.queue[0], after=lambda _: self.bot.loop.call_soon_threadsafe(self.next.set))
  File "C:\Users\ProPCUser\PycharmProjects\lycproject\venv\lib\site-packages\discord\voice_client.py", line 608, in play
    raise ClientException('Already playing audio.')
discord.errors.ClientException: Already playing audio.

The above exception was the direct cause of the following exception:

Traceback (most recent call last):
  File "C:\Users\ProPCUser\PycharmProjects\lycproject\venv\lib\site-packages\discord\ext\commands\bot.py", line 1350, in invoke
    await ctx.command.invoke(ctx)
  File "C:\Users\ProPCUser\PycharmProjects\lycproject\venv\lib\site-packages\discord\ext\commands\core.py", line 1029, in invoke
    await injected(*ctx.args, **ctx.kwargs)  # type: ignore
  File "C:\Users\ProPCUser\PycharmProjects\lycproject\venv\lib\site-packages\discord\ext\commands\core.py", line 244, in wrapped
    raise CommandInvokeError(exc) from exc
discord.ext.commands.errors.CommandInvokeError: Command raised an exception: ClientException: Already playing audio.
Ignoring exception in command add_queue
Traceback (most recent call last):
  File "C:\Users\ProPCUser\PycharmProjects\lycproject\venv\lib\site-packages\discord\ext\commands\core.py", line 235, in wrapped
    ret = await coro(*args, **kwargs)
  File "C:\Users\ProPCUser\PycharmProjects\lycproject\cogs\music_bot.py", line 136, in add_queue
    await self._await.put(await self.start_playing(ctx, ctx.voice_client))
  File "C:\Users\ProPCUser\PycharmProjects\lycproject\cogs\music_bot.py", line 124, in start_playing
    voice_client.play(self.queue[0], after=lambda _: self.bot.loop.call_soon_threadsafe(self.next.set))
  File "C:\Users\ProPCUser\PycharmProjects\lycproject\venv\lib\site-packages\discord\voice_client.py", line 608, in play
    raise ClientException('Already playing audio.')
discord.errors.ClientException: Already playing audio.

The above exception was the direct cause of the following exception:

Traceback (most recent call last):
  File "C:\Users\ProPCUser\PycharmProjects\lycproject\venv\lib\site-packages\discord\ext\commands\bot.py", line 1350, in invoke
    await ctx.command.invoke(ctx)
  File "C:\Users\ProPCUser\PycharmProjects\lycproject\venv\lib\site-packages\discord\ext\commands\core.py", line 1029, in invoke
    await injected(*ctx.args, **ctx.kwargs)  # type: ignore
  File "C:\Users\ProPCUser\PycharmProjects\lycproject\venv\lib\site-packages\discord\ext\commands\core.py", line 244, in wrapped
    raise CommandInvokeError(exc) from exc
discord.ext.commands.errors.CommandInvokeError: Command raised an exception: ClientException: Already playing audio.
Ignoring exception in command add_queue
Traceback (most recent call last):
  File "C:\Users\ProPCUser\PycharmProjects\lycproject\venv\lib\site-packages\discord\ext\commands\core.py", line 235, in wrapped
    ret = await coro(*args, **kwargs)
  File "C:\Users\ProPCUser\PycharmProjects\lycproject\cogs\music_bot.py", line 136, in add_queue
    await self._await.put(await self.start_playing(ctx, ctx.voice_client))
  File "C:\Users\ProPCUser\PycharmProjects\lycproject\cogs\music_bot.py", line 124, in start_playing
    voice_client.play(self.queue[0], after=lambda _: self.bot.loop.call_soon_threadsafe(self.next.set))
  File "C:\Users\ProPCUser\PycharmProjects\lycproject\venv\lib\site-packages\discord\voice_client.py", line 608, in play
    raise ClientException('Already playing audio.')
discord.errors.ClientException: Already playing audio.

The above exception was the direct cause of the following exception:

Traceback (most recent call last):
  File "C:\Users\ProPCUser\PycharmProjects\lycproject\venv\lib\site-packages\discord\ext\commands\bot.py", line 1350, in invoke
    await ctx.command.invoke(ctx)
  File "C:\Users\ProPCUser\PycharmProjects\lycproject\venv\lib\site-packages\discord\ext\commands\core.py", line 1029, in invoke
    await injected(*ctx.args, **ctx.kwargs)  # type: ignore
  File "C:\Users\ProPCUser\PycharmProjects\lycproject\venv\lib\site-packages\discord\ext\commands\core.py", line 244, in wrapped
    raise CommandInvokeError(exc) from exc
discord.ext.commands.errors.CommandInvokeError: Command raised an exception: ClientException: Already playing audio.
Ignoring exception in command music
Traceback (most recent call last):
  File "C:\Users\ProPCUser\PycharmProjects\lycproject\venv\lib\site-packages\discord\ext\commands\core.py", line 235, in wrapped
    ret = await coro(*args, **kwargs)
  File "C:\Users\ProPCUser\PycharmProjects\lycproject\cogs\music_bot.py", line 91, in music
    ctx.bot.loop.run_until_complete(self.music_loop(ctx))
  File "C:\Users\ProPCUser\AppData\Local\Programs\Python\Python38\lib\asyncio\base_events.py", line 592, in run_until_complete
    self._check_running()
  File "C:\Users\ProPCUser\AppData\Local\Programs\Python\Python38\lib\asyncio\base_events.py", line 552, in _check_running
    raise RuntimeError('This event loop is already running')
RuntimeError: This event loop is already running

The above exception was the direct cause of the following exception:

Traceback (most recent call last):
  File "C:\Users\ProPCUser\PycharmProjects\lycproject\venv\lib\site-packages\discord\ext\commands\bot.py", line 1350, in invoke
    await ctx.command.invoke(ctx)
  File "C:\Users\ProPCUser\PycharmProjects\lycproject\venv\lib\site-packages\discord\ext\commands\core.py", line 1029, in invoke
    await injected(*ctx.args, **ctx.kwargs)  # type: ignore
  File "C:\Users\ProPCUser\PycharmProjects\lycproject\venv\lib\site-packages\discord\ext\commands\core.py", line 244, in wrapped
    raise CommandInvokeError(exc) from exc
discord.ext.commands.errors.CommandInvokeError: Command raised an exception: RuntimeError: This event loop is already running
Ignoring exception in command None
discord.ext.commands.errors.CommandNotFound: Command "test" is not found
Ignoring exception in command test
Traceback (most recent call last):
  File "C:\Users\ProPCUser\PycharmProjects\lycproject\venv\lib\site-packages\discord\ext\commands\core.py", line 235, in wrapped
    ret = await coro(*args, **kwargs)
  File "C:\Users\ProPCUser\PycharmProjects\lycproject\main.py", line 49, in test
    await interaction.response.send_modal(Questionnaire())
AttributeError: 'Context' object has no attribute 'response'

The above exception was the direct cause of the following exception:

Traceback (most recent call last):
  File "C:\Users\ProPCUser\PycharmProjects\lycproject\venv\lib\site-packages\discord\ext\commands\bot.py", line 1350, in invoke
    await ctx.command.invoke(ctx)
  File "C:\Users\ProPCUser\PycharmProjects\lycproject\venv\lib\site-packages\discord\ext\commands\core.py", line 1029, in invoke
    await injected(*ctx.args, **ctx.kwargs)  # type: ignore
  File "C:\Users\ProPCUser\PycharmProjects\lycproject\venv\lib\site-packages\discord\ext\commands\core.py", line 244, in wrapped
    raise CommandInvokeError(exc) from exc
discord.ext.commands.errors.CommandInvokeError: Command raised an exception: AttributeError: 'Context' object has no attribute 'response'
Ignoring exception in command test
Traceback (most recent call last):
  File "C:\Users\ProPCUser\PycharmProjects\lycproject\venv\lib\site-packages\discord\ext\commands\bot.py", line 1350, in invoke
    await ctx.command.invoke(ctx)
  File "C:\Users\ProPCUser\PycharmProjects\lycproject\venv\lib\site-packages\discord\ext\commands\core.py", line 1021, in invoke
    await self.prepare(ctx)
  File "C:\Users\ProPCUser\PycharmProjects\lycproject\venv\lib\site-packages\discord\ext\commands\core.py", line 938, in prepare
    await self._parse_arguments(ctx)
  File "C:\Users\ProPCUser\PycharmProjects\lycproject\venv\lib\site-packages\discord\ext\commands\core.py", line 845, in _parse_arguments
    transformed = await self.transform(ctx, param, attachments)
  File "C:\Users\ProPCUser\PycharmProjects\lycproject\venv\lib\site-packages\discord\ext\commands\core.py", line 697, in transform
    raise MissingRequiredArgument(param)
discord.ext.commands.errors.MissingRequiredArgument: interaction is a required argument that is missing.
Ignoring exception in command None
discord.ext.commands.errors.CommandNotFound: Command "test" is not found
Ignoring exception in command test
Traceback (most recent call last):
  File "C:\Users\ProPCUser\PycharmProjects\lycproject\venv\lib\site-packages\discord\ext\commands\core.py", line 235, in wrapped
    ret = await coro(*args, **kwargs)
  File "C:\Users\ProPCUser\PycharmProjects\lycproject\cogs\default_cogs.py", line 45, in test
    await interaction.response.send_modal(Schedule())
AttributeError: 'Context' object has no attribute 'response'

The above exception was the direct cause of the following exception:

Traceback (most recent call last):
  File "C:\Users\ProPCUser\PycharmProjects\lycproject\venv\lib\site-packages\discord\ext\commands\bot.py", line 1350, in invoke
    await ctx.command.invoke(ctx)
  File "C:\Users\ProPCUser\PycharmProjects\lycproject\venv\lib\site-packages\discord\ext\commands\core.py", line 1029, in invoke
    await injected(*ctx.args, **ctx.kwargs)  # type: ignore
  File "C:\Users\ProPCUser\PycharmProjects\lycproject\venv\lib\site-packages\discord\ext\commands\core.py", line 244, in wrapped
    raise CommandInvokeError(exc) from exc
discord.ext.commands.errors.CommandInvokeError: Command raised an exception: AttributeError: 'Context' object has no attribute 'response'
Ignoring exception in command None
discord.ext.commands.errors.CommandNotFound: Command "test" is not found
Ignoring exception in command None
discord.ext.commands.errors.CommandNotFound: Command "test" is not found
Ignoring exception in command None
discord.ext.commands.errors.CommandNotFound: Command "test" is not found
Ignoring exception in command None
discord.ext.commands.errors.CommandNotFound: Command "tree" is not found
Ignoring exception in command None
discord.ext.commands.errors.CommandNotFound: Command "test" is not found
Ignoring exception in command None
discord.ext.commands.errors.CommandNotFound: Command "abc" is not found
Ignoring exception in command None
discord.ext.commands.errors.CommandNotFound: Command "tree" is not found
Ignoring exception in command None
discord.ext.commands.errors.CommandNotFound: Command "tree" is not found
Ignoring exception in command None
discord.ext.commands.errors.CommandNotFound: Command "tree" is not found
Ignoring exception in command None
discord.ext.commands.errors.CommandNotFound: Command "text" is not found
Ignoring exception in command abc
Traceback (most recent call last):
  File "C:\Users\ProPCUser\PycharmProjects\lycproject\venv\lib\site-packages\discord\ext\commands\core.py", line 235, in wrapped
    ret = await coro(*args, **kwargs)
  File "C:\Users\ProPCUser\PycharmProjects\lycproject\main.py", line 51, in test
    await interaction.response.send_message('Hey!')
AttributeError: 'Context' object has no attribute 'response'

The above exception was the direct cause of the following exception:

Traceback (most recent call last):
  File "C:\Users\ProPCUser\PycharmProjects\lycproject\venv\lib\site-packages\discord\ext\commands\bot.py", line 1350, in invoke
    await ctx.command.invoke(ctx)
  File "C:\Users\ProPCUser\PycharmProjects\lycproject\venv\lib\site-packages\discord\ext\commands\core.py", line 1029, in invoke
    await injected(*ctx.args, **ctx.kwargs)  # type: ignore
  File "C:\Users\ProPCUser\PycharmProjects\lycproject\venv\lib\site-packages\discord\ext\commands\core.py", line 244, in wrapped
    raise CommandInvokeError(exc) from exc
discord.ext.commands.errors.CommandInvokeError: Command raised an exception: AttributeError: 'Context' object has no attribute 'response'
Ignoring exception in command None
discord.ext.commands.errors.CommandNotFound: Command "abc" is not found
Ignoring exception in command None
discord.ext.commands.errors.CommandNotFound: Command "test" is not found
Ignoring exception in command remove_queue
Traceback (most recent call last):
  File "C:\Users\ProPCUser\PycharmProjects\lycproject\venv\lib\site-packages\discord\app_commands\commands.py", line 827, in _do_call
    return await self._callback(self.binding, interaction, **params)  # type: ignore
  File "C:\Users\ProPCUser\PycharmProjects\lycproject\cogs\music_bot.py", line 137, in remove_queue
    self.queue.pop(number)
TypeError: 'str' object cannot be interpreted as an integer

The above exception was the direct cause of the following exception:

Traceback (most recent call last):
  File "C:\Users\ProPCUser\PycharmProjects\lycproject\venv\lib\site-packages\discord\ext\commands\hybrid.py", line 438, in _invoke_with_namespace
    value = await self._do_call(ctx, ctx.kwargs)  # type: ignore
  File "C:\Users\ProPCUser\PycharmProjects\lycproject\venv\lib\site-packages\discord\app_commands\commands.py", line 842, in _do_call
    raise CommandInvokeError(self, e) from e
discord.app_commands.errors.CommandInvokeError: Command 'remove_queue' raised an exception: TypeError: 'str' object cannot be interpreted as an integer

The above exception was the direct cause of the following exception:

Traceback (most recent call last):
  File "C:\Users\ProPCUser\PycharmProjects\lycproject\venv\lib\site-packages\discord\ext\commands\hybrid.py", line 438, in _invoke_with_namespace
    value = await self._do_call(ctx, ctx.kwargs)  # type: ignore
  File "C:\Users\ProPCUser\PycharmProjects\lycproject\venv\lib\site-packages\discord\app_commands\commands.py", line 842, in _do_call
    raise CommandInvokeError(self, e) from e
discord.ext.commands.errors.HybridCommandError: Hybrid command raised an error: Command 'remove_queue' raised an exception: TypeError: 'str' object cannot be interpreted as an integer
Ignoring exception in command None
discord.ext.commands.errors.CommandNotFound: Command "test" is not found
Ignoring exception in command 'test'
Traceback (most recent call last):
  File "C:\Users\ProPCUser\PycharmProjects\lycproject\venv\lib\site-packages\discord\app_commands\commands.py", line 828, in _do_call
    return await self._callback(interaction, **params)  # type: ignore
  File "C:\Users\ProPCUser\PycharmProjects\lycproject\main.py", line 46, in test
    await interaction.response.send_modal(Schedule())
  File "C:\Users\ProPCUser\PycharmProjects\lycproject\venv\lib\site-packages\discord\interactions.py", line 964, in send_modal
    raise InteractionResponded(self._parent)
discord.errors.InteractionResponded: This interaction has already been responded to before

The above exception was the direct cause of the following exception:

Traceback (most recent call last):
  File "C:\Users\ProPCUser\PycharmProjects\lycproject\venv\lib\site-packages\discord\app_commands\tree.py", line 1248, in _call
    await command._invoke_with_namespace(interaction, namespace)
  File "C:\Users\ProPCUser\PycharmProjects\lycproject\venv\lib\site-packages\discord\app_commands\commands.py", line 853, in _invoke_with_namespace
    return await self._do_call(interaction, transformed_values)
  File "C:\Users\ProPCUser\PycharmProjects\lycproject\venv\lib\site-packages\discord\app_commands\commands.py", line 846, in _do_call
    raise CommandInvokeError(self, e) from e
discord.app_commands.errors.CommandInvokeError: Command 'test' raised an exception: InteractionResponded: This interaction has already been responded to before
Ignoring exception in command 'abc'
Traceback (most recent call last):
  File "C:\Users\ProPCUser\PycharmProjects\lycproject\venv\lib\site-packages\discord\app_commands\commands.py", line 828, in _do_call
    return await self._callback(interaction, **params)  # type: ignore
  File "C:\Users\ProPCUser\PycharmProjects\lycproject\main.py", line 53, in test
    await interaction.response.send_modal(Schedule())
  File "C:\Users\ProPCUser\PycharmProjects\lycproject\venv\lib\site-packages\discord\interactions.py", line 972, in send_modal
    await adapter.create_interaction_response(
  File "C:\Users\ProPCUser\PycharmProjects\lycproject\venv\lib\site-packages\discord\webhook\async_.py", line 221, in request
    raise HTTPException(response, data)
discord.errors.HTTPException: 400 Bad Request (error code: 50035): Invalid Form Body
In data.components.3.components.0: Value of field "type" must be one of (4,).

The above exception was the direct cause of the following exception:

Traceback (most recent call last):
  File "C:\Users\ProPCUser\PycharmProjects\lycproject\venv\lib\site-packages\discord\app_commands\tree.py", line 1248, in _call
    await command._invoke_with_namespace(interaction, namespace)
  File "C:\Users\ProPCUser\PycharmProjects\lycproject\venv\lib\site-packages\discord\app_commands\commands.py", line 853, in _invoke_with_namespace
    return await self._do_call(interaction, transformed_values)
  File "C:\Users\ProPCUser\PycharmProjects\lycproject\venv\lib\site-packages\discord\app_commands\commands.py", line 846, in _do_call
    raise CommandInvokeError(self, e) from e
discord.app_commands.errors.CommandInvokeError: Command 'abc' raised an exception: HTTPException: 400 Bad Request (error code: 50035): Invalid Form Body
In data.components.3.components.0: Value of field "type" must be one of (4,).
Attempting a reconnect in 1.28s
Traceback (most recent call last):
  File "C:\Users\ProPCUser\PycharmProjects\lycproject\venv\lib\site-packages\discord\client.py", line 659, in connect
    await self.ws.poll_event()
  File "C:\Users\ProPCUser\PycharmProjects\lycproject\venv\lib\site-packages\discord\gateway.py", line 646, in poll_event
    raise ConnectionClosed(self.socket, shard_id=self.shard_id, code=code) from None
discord.errors.ConnectionClosed: Shard ID None WebSocket closed with 1000
Ignoring exception in command 'abc'
Traceback (most recent call last):
  File "C:\Users\ProPCUser\PycharmProjects\lycproject\venv\lib\site-packages\discord\app_commands\commands.py", line 828, in _do_call
    return await self._callback(interaction, **params)  # type: ignore
  File "C:\Users\ProPCUser\PycharmProjects\lycproject\main.py", line 53, in test
    await interaction.response.send_modal(Schedule())
  File "C:\Users\ProPCUser\PycharmProjects\lycproject\venv\lib\site-packages\discord\interactions.py", line 972, in send_modal
    await adapter.create_interaction_response(
  File "C:\Users\ProPCUser\PycharmProjects\lycproject\venv\lib\site-packages\discord\webhook\async_.py", line 221, in request
    raise HTTPException(response, data)
discord.errors.HTTPException: 400 Bad Request (error code: 50035): Invalid Form Body
In data.components.3.components.0.options: This field is required

The above exception was the direct cause of the following exception:

Traceback (most recent call last):
  File "C:\Users\ProPCUser\PycharmProjects\lycproject\venv\lib\site-packages\discord\app_commands\tree.py", line 1248, in _call
    await command._invoke_with_namespace(interaction, namespace)
  File "C:\Users\ProPCUser\PycharmProjects\lycproject\venv\lib\site-packages\discord\app_commands\commands.py", line 853, in _invoke_with_namespace
    return await self._do_call(interaction, transformed_values)
  File "C:\Users\ProPCUser\PycharmProjects\lycproject\venv\lib\site-packages\discord\app_commands\commands.py", line 846, in _do_call
    raise CommandInvokeError(self, e) from e
discord.app_commands.errors.CommandInvokeError: Command 'abc' raised an exception: HTTPException: 400 Bad Request (error code: 50035): Invalid Form Body
In data.components.3.components.0.options: This field is required
Ignoring exception in command 'abc'
Traceback (most recent call last):
  File "C:\Users\ProPCUser\PycharmProjects\lycproject\venv\lib\site-packages\discord\app_commands\commands.py", line 828, in _do_call
    return await self._callback(interaction, **params)  # type: ignore
  File "C:\Users\ProPCUser\PycharmProjects\lycproject\main.py", line 53, in test
    await interaction.response.send_modal(Schedule())
  File "C:\Users\ProPCUser\PycharmProjects\lycproject\venv\lib\site-packages\discord\interactions.py", line 972, in send_modal
    await adapter.create_interaction_response(
  File "C:\Users\ProPCUser\PycharmProjects\lycproject\venv\lib\site-packages\discord\webhook\async_.py", line 221, in request
    raise HTTPException(response, data)
discord.errors.HTTPException: 400 Bad Request (error code: 50035): Invalid Form Body
In data.components.3.components.0.options: Must be 10 or more in length.

The above exception was the direct cause of the following exception:

Traceback (most recent call last):
  File "C:\Users\ProPCUser\PycharmProjects\lycproject\venv\lib\site-packages\discord\app_commands\tree.py", line 1248, in _call
    await command._invoke_with_namespace(interaction, namespace)
  File "C:\Users\ProPCUser\PycharmProjects\lycproject\venv\lib\site-packages\discord\app_commands\commands.py", line 853, in _invoke_with_namespace
    return await self._do_call(interaction, transformed_values)
  File "C:\Users\ProPCUser\PycharmProjects\lycproject\venv\lib\site-packages\discord\app_commands\commands.py", line 846, in _do_call
    raise CommandInvokeError(self, e) from e
discord.app_commands.errors.CommandInvokeError: Command 'abc' raised an exception: HTTPException: 400 Bad Request (error code: 50035): Invalid Form Body
In data.components.3.components.0.options: Must be 10 or more in length.
Ignoring exception in command 'abc'
Traceback (most recent call last):
  File "C:\Users\ProPCUser\PycharmProjects\lycproject\venv\lib\site-packages\discord\app_commands\commands.py", line 828, in _do_call
    return await self._callback(interaction, **params)  # type: ignore
  File "C:\Users\ProPCUser\PycharmProjects\lycproject\main.py", line 53, in test
    await interaction.response.send_modal(Schedule())
  File "C:\Users\ProPCUser\PycharmProjects\lycproject\venv\lib\site-packages\discord\interactions.py", line 972, in send_modal
    await adapter.create_interaction_response(
  File "C:\Users\ProPCUser\PycharmProjects\lycproject\venv\lib\site-packages\discord\webhook\async_.py", line 221, in request
    raise HTTPException(response, data)
discord.errors.HTTPException: 400 Bad Request (error code: 50035): Invalid Form Body
In data.components.3.components.0: Value of field "type" must be one of (4,).

The above exception was the direct cause of the following exception:

Traceback (most recent call last):
  File "C:\Users\ProPCUser\PycharmProjects\lycproject\venv\lib\site-packages\discord\app_commands\tree.py", line 1248, in _call
    await command._invoke_with_namespace(interaction, namespace)
  File "C:\Users\ProPCUser\PycharmProjects\lycproject\venv\lib\site-packages\discord\app_commands\commands.py", line 853, in _invoke_with_namespace
    return await self._do_call(interaction, transformed_values)
  File "C:\Users\ProPCUser\PycharmProjects\lycproject\venv\lib\site-packages\discord\app_commands\commands.py", line 846, in _do_call
    raise CommandInvokeError(self, e) from e
discord.app_commands.errors.CommandInvokeError: Command 'abc' raised an exception: HTTPException: 400 Bad Request (error code: 50035): Invalid Form Body
In data.components.3.components.0: Value of field "type" must be one of (4,).
Ignoring exception in command 'abc'
Traceback (most recent call last):
  File "C:\Users\ProPCUser\PycharmProjects\lycproject\venv\lib\site-packages\discord\app_commands\commands.py", line 828, in _do_call
    return await self._callback(interaction, **params)  # type: ignore
  File "C:\Users\ProPCUser\PycharmProjects\lycproject\main.py", line 53, in test
    await interaction.response.send_modal(Schedule())
  File "C:\Users\ProPCUser\PycharmProjects\lycproject\venv\lib\site-packages\discord\interactions.py", line 972, in send_modal
    await adapter.create_interaction_response(
  File "C:\Users\ProPCUser\PycharmProjects\lycproject\venv\lib\site-packages\discord\webhook\async_.py", line 221, in request
    raise HTTPException(response, data)
discord.errors.HTTPException: 400 Bad Request (error code: 50035): Invalid Form Body
In data.components.3.components.0: Value of field "type" must be one of (4,).

The above exception was the direct cause of the following exception:

Traceback (most recent call last):
  File "C:\Users\ProPCUser\PycharmProjects\lycproject\venv\lib\site-packages\discord\app_commands\tree.py", line 1248, in _call
    await command._invoke_with_namespace(interaction, namespace)
  File "C:\Users\ProPCUser\PycharmProjects\lycproject\venv\lib\site-packages\discord\app_commands\commands.py", line 853, in _invoke_with_namespace
    return await self._do_call(interaction, transformed_values)
  File "C:\Users\ProPCUser\PycharmProjects\lycproject\venv\lib\site-packages\discord\app_commands\commands.py", line 846, in _do_call
    raise CommandInvokeError(self, e) from e
discord.app_commands.errors.CommandInvokeError: Command 'abc' raised an exception: HTTPException: 400 Bad Request (error code: 50035): Invalid Form Body
In data.components.3.components.0: Value of field "type" must be one of (4,).
Ignoring exception in command 'abc'
Traceback (most recent call last):
  File "C:\Users\ProPCUser\PycharmProjects\lycproject\venv\lib\site-packages\discord\app_commands\commands.py", line 828, in _do_call
    return await self._callback(interaction, **params)  # type: ignore
  File "C:\Users\ProPCUser\PycharmProjects\lycproject\main.py", line 53, in test
    await interaction.response.send_modal(Schedule())
  File "C:\Users\ProPCUser\PycharmProjects\lycproject\venv\lib\site-packages\discord\interactions.py", line 971, in send_modal
    params = interaction_response_params(InteractionResponseType.modal.value, modal.to_dict())
AttributeError: 'Schedule' object has no attribute 'to_dict'

The above exception was the direct cause of the following exception:

Traceback (most recent call last):
  File "C:\Users\ProPCUser\PycharmProjects\lycproject\venv\lib\site-packages\discord\app_commands\tree.py", line 1248, in _call
    await command._invoke_with_namespace(interaction, namespace)
  File "C:\Users\ProPCUser\PycharmProjects\lycproject\venv\lib\site-packages\discord\app_commands\commands.py", line 853, in _invoke_with_namespace
    return await self._do_call(interaction, transformed_values)
  File "C:\Users\ProPCUser\PycharmProjects\lycproject\venv\lib\site-packages\discord\app_commands\commands.py", line 846, in _do_call
    raise CommandInvokeError(self, e) from e
discord.app_commands.errors.CommandInvokeError: Command 'abc' raised an exception: AttributeError: 'Schedule' object has no attribute 'to_dict'
Ignoring exception in modal <Schedule timeout=None children=3>:
Traceback (most recent call last):
  File "C:\Users\ProPCUser\PycharmProjects\lycproject\venv\lib\site-packages\discord\ui\modal.py", line 188, in _scheduled_task
    await self.on_submit(interaction)
  File "C:\Users\ProPCUser\PycharmProjects\lycproject\technical.py", line 29, in on_submit
    for member in discord.Interaction.guild.members:
AttributeError: 'property' object has no attribute 'members'
Attempting a reconnect in 0.78s
Traceback (most recent call last):
  File "C:\Users\ProPCUser\PycharmProjects\lycproject\venv\lib\site-packages\aiohttp\connector.py", line 1203, in _create_direct_connection
    hosts = await self._resolve_host(host, port, traces=traces)
  File "C:\Users\ProPCUser\PycharmProjects\lycproject\venv\lib\site-packages\aiohttp\connector.py", line 880, in _resolve_host
    return await asyncio.shield(resolved_host_task)
  File "C:\Users\ProPCUser\PycharmProjects\lycproject\venv\lib\site-packages\aiohttp\connector.py", line 917, in _resolve_host_with_throttle
    addrs = await self._resolver.resolve(host, port, family=self._family)
  File "C:\Users\ProPCUser\PycharmProjects\lycproject\venv\lib\site-packages\aiohttp\resolver.py", line 33, in resolve
    infos = await self._loop.getaddrinfo(
  File "C:\Users\ProPCUser\AppData\Local\Programs\Python\Python38\lib\asyncio\base_events.py", line 825, in getaddrinfo
    return await self.run_in_executor(
  File "C:\Users\ProPCUser\AppData\Local\Programs\Python\Python38\lib\concurrent\futures\thread.py", line 57, in run
    result = self.fn(*self.args, **self.kwargs)
  File "C:\Users\ProPCUser\AppData\Local\Programs\Python\Python38\lib\socket.py", line 918, in getaddrinfo
    for res in _socket.getaddrinfo(host, port, family, type, proto, flags):
socket.gaierror: [Errno 11001] getaddrinfo failed

The above exception was the direct cause of the following exception:

Traceback (most recent call last):
  File "C:\Users\ProPCUser\PycharmProjects\lycproject\venv\lib\site-packages\discord\client.py", line 656, in connect
    self.ws = await asyncio.wait_for(coro, timeout=60.0)
  File "C:\Users\ProPCUser\AppData\Local\Programs\Python\Python38\lib\asyncio\tasks.py", line 491, in wait_for
    return fut.result()
  File "C:\Users\ProPCUser\PycharmProjects\lycproject\venv\lib\site-packages\discord\gateway.py", line 372, in from_client
    socket = await client.http.ws_connect(str(url))
  File "C:\Users\ProPCUser\PycharmProjects\lycproject\venv\lib\site-packages\discord\http.py", line 537, in ws_connect
    return await self.__session.ws_connect(url, **kwargs)
  File "C:\Users\ProPCUser\PycharmProjects\lycproject\venv\lib\site-packages\aiohttp\client.py", line 835, in _ws_connect
    resp = await self.request(
  File "C:\Users\ProPCUser\PycharmProjects\lycproject\venv\lib\site-packages\aiohttp\client.py", line 581, in _request
    conn = await self._connector.connect(
  File "C:\Users\ProPCUser\PycharmProjects\lycproject\venv\lib\site-packages\aiohttp\connector.py", line 544, in connect
    proto = await self._create_connection(req, traces, timeout)
  File "C:\Users\ProPCUser\PycharmProjects\lycproject\venv\lib\site-packages\aiohttp\connector.py", line 944, in _create_connection
    _, proto = await self._create_direct_connection(req, traces, timeout)
  File "C:\Users\ProPCUser\PycharmProjects\lycproject\venv\lib\site-packages\aiohttp\connector.py", line 1209, in _create_direct_connection
    raise ClientConnectorError(req.connection_key, exc) from exc
aiohttp.client_exceptions.ClientConnectorError: Cannot connect to host gateway-us-east1-b.discord.gg:443 ssl:default [getaddrinfo failed]
Attempting a reconnect in 3.72s
Traceback (most recent call last):
  File "C:\Users\ProPCUser\PycharmProjects\lycproject\venv\lib\site-packages\aiohttp\connector.py", line 1203, in _create_direct_connection
    hosts = await self._resolve_host(host, port, traces=traces)
  File "C:\Users\ProPCUser\PycharmProjects\lycproject\venv\lib\site-packages\aiohttp\connector.py", line 880, in _resolve_host
    return await asyncio.shield(resolved_host_task)
  File "C:\Users\ProPCUser\PycharmProjects\lycproject\venv\lib\site-packages\aiohttp\connector.py", line 917, in _resolve_host_with_throttle
    addrs = await self._resolver.resolve(host, port, family=self._family)
  File "C:\Users\ProPCUser\PycharmProjects\lycproject\venv\lib\site-packages\aiohttp\resolver.py", line 33, in resolve
    infos = await self._loop.getaddrinfo(
  File "C:\Users\ProPCUser\AppData\Local\Programs\Python\Python38\lib\asyncio\base_events.py", line 825, in getaddrinfo
    return await self.run_in_executor(
  File "C:\Users\ProPCUser\AppData\Local\Programs\Python\Python38\lib\concurrent\futures\thread.py", line 57, in run
    result = self.fn(*self.args, **self.kwargs)
  File "C:\Users\ProPCUser\AppData\Local\Programs\Python\Python38\lib\socket.py", line 918, in getaddrinfo
    for res in _socket.getaddrinfo(host, port, family, type, proto, flags):
socket.gaierror: [Errno 11001] getaddrinfo failed

The above exception was the direct cause of the following exception:

Traceback (most recent call last):
  File "C:\Users\ProPCUser\PycharmProjects\lycproject\venv\lib\site-packages\discord\client.py", line 656, in connect
    self.ws = await asyncio.wait_for(coro, timeout=60.0)
  File "C:\Users\ProPCUser\AppData\Local\Programs\Python\Python38\lib\asyncio\tasks.py", line 491, in wait_for
    return fut.result()
  File "C:\Users\ProPCUser\PycharmProjects\lycproject\venv\lib\site-packages\discord\gateway.py", line 372, in from_client
    socket = await client.http.ws_connect(str(url))
  File "C:\Users\ProPCUser\PycharmProjects\lycproject\venv\lib\site-packages\discord\http.py", line 537, in ws_connect
    return await self.__session.ws_connect(url, **kwargs)
  File "C:\Users\ProPCUser\PycharmProjects\lycproject\venv\lib\site-packages\aiohttp\client.py", line 835, in _ws_connect
    resp = await self.request(
  File "C:\Users\ProPCUser\PycharmProjects\lycproject\venv\lib\site-packages\aiohttp\client.py", line 581, in _request
    conn = await self._connector.connect(
  File "C:\Users\ProPCUser\PycharmProjects\lycproject\venv\lib\site-packages\aiohttp\connector.py", line 544, in connect
    proto = await self._create_connection(req, traces, timeout)
  File "C:\Users\ProPCUser\PycharmProjects\lycproject\venv\lib\site-packages\aiohttp\connector.py", line 944, in _create_connection
    _, proto = await self._create_direct_connection(req, traces, timeout)
  File "C:\Users\ProPCUser\PycharmProjects\lycproject\venv\lib\site-packages\aiohttp\connector.py", line 1209, in _create_direct_connection
    raise ClientConnectorError(req.connection_key, exc) from exc
aiohttp.client_exceptions.ClientConnectorError: Cannot connect to host gateway-us-east1-b.discord.gg:443 ssl:default [getaddrinfo failed]
Attempting a reconnect in 5.71s
Traceback (most recent call last):
  File "C:\Users\ProPCUser\PycharmProjects\lycproject\venv\lib\site-packages\aiohttp\connector.py", line 1203, in _create_direct_connection
    hosts = await self._resolve_host(host, port, traces=traces)
  File "C:\Users\ProPCUser\PycharmProjects\lycproject\venv\lib\site-packages\aiohttp\connector.py", line 880, in _resolve_host
    return await asyncio.shield(resolved_host_task)
  File "C:\Users\ProPCUser\PycharmProjects\lycproject\venv\lib\site-packages\aiohttp\connector.py", line 917, in _resolve_host_with_throttle
    addrs = await self._resolver.resolve(host, port, family=self._family)
  File "C:\Users\ProPCUser\PycharmProjects\lycproject\venv\lib\site-packages\aiohttp\resolver.py", line 33, in resolve
    infos = await self._loop.getaddrinfo(
  File "C:\Users\ProPCUser\AppData\Local\Programs\Python\Python38\lib\asyncio\base_events.py", line 825, in getaddrinfo
    return await self.run_in_executor(
  File "C:\Users\ProPCUser\AppData\Local\Programs\Python\Python38\lib\concurrent\futures\thread.py", line 57, in run
    result = self.fn(*self.args, **self.kwargs)
  File "C:\Users\ProPCUser\AppData\Local\Programs\Python\Python38\lib\socket.py", line 918, in getaddrinfo
    for res in _socket.getaddrinfo(host, port, family, type, proto, flags):
socket.gaierror: [Errno 11001] getaddrinfo failed

The above exception was the direct cause of the following exception:

Traceback (most recent call last):
  File "C:\Users\ProPCUser\PycharmProjects\lycproject\venv\lib\site-packages\discord\client.py", line 656, in connect
    self.ws = await asyncio.wait_for(coro, timeout=60.0)
  File "C:\Users\ProPCUser\AppData\Local\Programs\Python\Python38\lib\asyncio\tasks.py", line 491, in wait_for
    return fut.result()
  File "C:\Users\ProPCUser\PycharmProjects\lycproject\venv\lib\site-packages\discord\gateway.py", line 372, in from_client
    socket = await client.http.ws_connect(str(url))
  File "C:\Users\ProPCUser\PycharmProjects\lycproject\venv\lib\site-packages\discord\http.py", line 537, in ws_connect
    return await self.__session.ws_connect(url, **kwargs)
  File "C:\Users\ProPCUser\PycharmProjects\lycproject\venv\lib\site-packages\aiohttp\client.py", line 835, in _ws_connect
    resp = await self.request(
  File "C:\Users\ProPCUser\PycharmProjects\lycproject\venv\lib\site-packages\aiohttp\client.py", line 581, in _request
    conn = await self._connector.connect(
  File "C:\Users\ProPCUser\PycharmProjects\lycproject\venv\lib\site-packages\aiohttp\connector.py", line 544, in connect
    proto = await self._create_connection(req, traces, timeout)
  File "C:\Users\ProPCUser\PycharmProjects\lycproject\venv\lib\site-packages\aiohttp\connector.py", line 944, in _create_connection
    _, proto = await self._create_direct_connection(req, traces, timeout)
  File "C:\Users\ProPCUser\PycharmProjects\lycproject\venv\lib\site-packages\aiohttp\connector.py", line 1209, in _create_direct_connection
    raise ClientConnectorError(req.connection_key, exc) from exc
aiohttp.client_exceptions.ClientConnectorError: Cannot connect to host gateway-us-east1-b.discord.gg:443 ssl:default [getaddrinfo failed]
Attempting a reconnect in 5.79s
Traceback (most recent call last):
  File "C:\Users\ProPCUser\PycharmProjects\lycproject\venv\lib\site-packages\aiohttp\connector.py", line 1203, in _create_direct_connection
    hosts = await self._resolve_host(host, port, traces=traces)
  File "C:\Users\ProPCUser\PycharmProjects\lycproject\venv\lib\site-packages\aiohttp\connector.py", line 880, in _resolve_host
    return await asyncio.shield(resolved_host_task)
  File "C:\Users\ProPCUser\PycharmProjects\lycproject\venv\lib\site-packages\aiohttp\connector.py", line 917, in _resolve_host_with_throttle
    addrs = await self._resolver.resolve(host, port, family=self._family)
  File "C:\Users\ProPCUser\PycharmProjects\lycproject\venv\lib\site-packages\aiohttp\resolver.py", line 33, in resolve
    infos = await self._loop.getaddrinfo(
  File "C:\Users\ProPCUser\AppData\Local\Programs\Python\Python38\lib\asyncio\base_events.py", line 825, in getaddrinfo
    return await self.run_in_executor(
  File "C:\Users\ProPCUser\AppData\Local\Programs\Python\Python38\lib\concurrent\futures\thread.py", line 57, in run
    result = self.fn(*self.args, **self.kwargs)
  File "C:\Users\ProPCUser\AppData\Local\Programs\Python\Python38\lib\socket.py", line 918, in getaddrinfo
    for res in _socket.getaddrinfo(host, port, family, type, proto, flags):
socket.gaierror: [Errno 11001] getaddrinfo failed

The above exception was the direct cause of the following exception:

Traceback (most recent call last):
  File "C:\Users\ProPCUser\PycharmProjects\lycproject\venv\lib\site-packages\discord\client.py", line 656, in connect
    self.ws = await asyncio.wait_for(coro, timeout=60.0)
  File "C:\Users\ProPCUser\AppData\Local\Programs\Python\Python38\lib\asyncio\tasks.py", line 491, in wait_for
    return fut.result()
  File "C:\Users\ProPCUser\PycharmProjects\lycproject\venv\lib\site-packages\discord\gateway.py", line 372, in from_client
    socket = await client.http.ws_connect(str(url))
  File "C:\Users\ProPCUser\PycharmProjects\lycproject\venv\lib\site-packages\discord\http.py", line 537, in ws_connect
    return await self.__session.ws_connect(url, **kwargs)
  File "C:\Users\ProPCUser\PycharmProjects\lycproject\venv\lib\site-packages\aiohttp\client.py", line 835, in _ws_connect
    resp = await self.request(
  File "C:\Users\ProPCUser\PycharmProjects\lycproject\venv\lib\site-packages\aiohttp\client.py", line 581, in _request
    conn = await self._connector.connect(
  File "C:\Users\ProPCUser\PycharmProjects\lycproject\venv\lib\site-packages\aiohttp\connector.py", line 544, in connect
    proto = await self._create_connection(req, traces, timeout)
  File "C:\Users\ProPCUser\PycharmProjects\lycproject\venv\lib\site-packages\aiohttp\connector.py", line 944, in _create_connection
    _, proto = await self._create_direct_connection(req, traces, timeout)
  File "C:\Users\ProPCUser\PycharmProjects\lycproject\venv\lib\site-packages\aiohttp\connector.py", line 1209, in _create_direct_connection
    raise ClientConnectorError(req.connection_key, exc) from exc
aiohttp.client_exceptions.ClientConnectorError: Cannot connect to host gateway-us-east1-b.discord.gg:443 ssl:default [getaddrinfo failed]
Attempting a reconnect in 3.19s
Traceback (most recent call last):
  File "C:\Users\ProPCUser\PycharmProjects\lycproject\venv\lib\site-packages\aiohttp\connector.py", line 1203, in _create_direct_connection
    hosts = await self._resolve_host(host, port, traces=traces)
  File "C:\Users\ProPCUser\PycharmProjects\lycproject\venv\lib\site-packages\aiohttp\connector.py", line 880, in _resolve_host
    return await asyncio.shield(resolved_host_task)
  File "C:\Users\ProPCUser\PycharmProjects\lycproject\venv\lib\site-packages\aiohttp\connector.py", line 917, in _resolve_host_with_throttle
    addrs = await self._resolver.resolve(host, port, family=self._family)
  File "C:\Users\ProPCUser\PycharmProjects\lycproject\venv\lib\site-packages\aiohttp\resolver.py", line 33, in resolve
    infos = await self._loop.getaddrinfo(
  File "C:\Users\ProPCUser\AppData\Local\Programs\Python\Python38\lib\asyncio\base_events.py", line 825, in getaddrinfo
    return await self.run_in_executor(
  File "C:\Users\ProPCUser\AppData\Local\Programs\Python\Python38\lib\concurrent\futures\thread.py", line 57, in run
    result = self.fn(*self.args, **self.kwargs)
  File "C:\Users\ProPCUser\AppData\Local\Programs\Python\Python38\lib\socket.py", line 918, in getaddrinfo
    for res in _socket.getaddrinfo(host, port, family, type, proto, flags):
socket.gaierror: [Errno 11001] getaddrinfo failed

The above exception was the direct cause of the following exception:

Traceback (most recent call last):
  File "C:\Users\ProPCUser\PycharmProjects\lycproject\venv\lib\site-packages\discord\client.py", line 656, in connect
    self.ws = await asyncio.wait_for(coro, timeout=60.0)
  File "C:\Users\ProPCUser\AppData\Local\Programs\Python\Python38\lib\asyncio\tasks.py", line 491, in wait_for
    return fut.result()
  File "C:\Users\ProPCUser\PycharmProjects\lycproject\venv\lib\site-packages\discord\gateway.py", line 372, in from_client
    socket = await client.http.ws_connect(str(url))
  File "C:\Users\ProPCUser\PycharmProjects\lycproject\venv\lib\site-packages\discord\http.py", line 537, in ws_connect
    return await self.__session.ws_connect(url, **kwargs)
  File "C:\Users\ProPCUser\PycharmProjects\lycproject\venv\lib\site-packages\aiohttp\client.py", line 835, in _ws_connect
    resp = await self.request(
  File "C:\Users\ProPCUser\PycharmProjects\lycproject\venv\lib\site-packages\aiohttp\client.py", line 581, in _request
    conn = await self._connector.connect(
  File "C:\Users\ProPCUser\PycharmProjects\lycproject\venv\lib\site-packages\aiohttp\connector.py", line 544, in connect
    proto = await self._create_connection(req, traces, timeout)
  File "C:\Users\ProPCUser\PycharmProjects\lycproject\venv\lib\site-packages\aiohttp\connector.py", line 944, in _create_connection
    _, proto = await self._create_direct_connection(req, traces, timeout)
  File "C:\Users\ProPCUser\PycharmProjects\lycproject\venv\lib\site-packages\aiohttp\connector.py", line 1209, in _create_direct_connection
    raise ClientConnectorError(req.connection_key, exc) from exc
aiohttp.client_exceptions.ClientConnectorError: Cannot connect to host gateway-us-east1-b.discord.gg:443 ssl:default [getaddrinfo failed]
Attempting a reconnect in 48.53s
Traceback (most recent call last):
  File "C:\Users\ProPCUser\PycharmProjects\lycproject\venv\lib\site-packages\aiohttp\connector.py", line 1203, in _create_direct_connection
    hosts = await self._resolve_host(host, port, traces=traces)
  File "C:\Users\ProPCUser\PycharmProjects\lycproject\venv\lib\site-packages\aiohttp\connector.py", line 880, in _resolve_host
    return await asyncio.shield(resolved_host_task)
  File "C:\Users\ProPCUser\PycharmProjects\lycproject\venv\lib\site-packages\aiohttp\connector.py", line 917, in _resolve_host_with_throttle
    addrs = await self._resolver.resolve(host, port, family=self._family)
  File "C:\Users\ProPCUser\PycharmProjects\lycproject\venv\lib\site-packages\aiohttp\resolver.py", line 33, in resolve
    infos = await self._loop.getaddrinfo(
  File "C:\Users\ProPCUser\AppData\Local\Programs\Python\Python38\lib\asyncio\base_events.py", line 825, in getaddrinfo
    return await self.run_in_executor(
  File "C:\Users\ProPCUser\AppData\Local\Programs\Python\Python38\lib\concurrent\futures\thread.py", line 57, in run
    result = self.fn(*self.args, **self.kwargs)
  File "C:\Users\ProPCUser\AppData\Local\Programs\Python\Python38\lib\socket.py", line 918, in getaddrinfo
    for res in _socket.getaddrinfo(host, port, family, type, proto, flags):
socket.gaierror: [Errno 11001] getaddrinfo failed

The above exception was the direct cause of the following exception:

Traceback (most recent call last):
  File "C:\Users\ProPCUser\PycharmProjects\lycproject\venv\lib\site-packages\discord\client.py", line 656, in connect
    self.ws = await asyncio.wait_for(coro, timeout=60.0)
  File "C:\Users\ProPCUser\AppData\Local\Programs\Python\Python38\lib\asyncio\tasks.py", line 491, in wait_for
    return fut.result()
  File "C:\Users\ProPCUser\PycharmProjects\lycproject\venv\lib\site-packages\discord\gateway.py", line 372, in from_client
    socket = await client.http.ws_connect(str(url))
  File "C:\Users\ProPCUser\PycharmProjects\lycproject\venv\lib\site-packages\discord\http.py", line 537, in ws_connect
    return await self.__session.ws_connect(url, **kwargs)
  File "C:\Users\ProPCUser\PycharmProjects\lycproject\venv\lib\site-packages\aiohttp\client.py", line 835, in _ws_connect
    resp = await self.request(
  File "C:\Users\ProPCUser\PycharmProjects\lycproject\venv\lib\site-packages\aiohttp\client.py", line 581, in _request
    conn = await self._connector.connect(
  File "C:\Users\ProPCUser\PycharmProjects\lycproject\venv\lib\site-packages\aiohttp\connector.py", line 544, in connect
    proto = await self._create_connection(req, traces, timeout)
  File "C:\Users\ProPCUser\PycharmProjects\lycproject\venv\lib\site-packages\aiohttp\connector.py", line 944, in _create_connection
    _, proto = await self._create_direct_connection(req, traces, timeout)
  File "C:\Users\ProPCUser\PycharmProjects\lycproject\venv\lib\site-packages\aiohttp\connector.py", line 1209, in _create_direct_connection
    raise ClientConnectorError(req.connection_key, exc) from exc
aiohttp.client_exceptions.ClientConnectorError: Cannot connect to host gateway-us-east1-b.discord.gg:443 ssl:default [getaddrinfo failed]
Attempting a reconnect in 44.58s
Traceback (most recent call last):
  File "C:\Users\ProPCUser\PycharmProjects\lycproject\venv\lib\site-packages\aiohttp\connector.py", line 1203, in _create_direct_connection
    hosts = await self._resolve_host(host, port, traces=traces)
  File "C:\Users\ProPCUser\PycharmProjects\lycproject\venv\lib\site-packages\aiohttp\connector.py", line 880, in _resolve_host
    return await asyncio.shield(resolved_host_task)
  File "C:\Users\ProPCUser\PycharmProjects\lycproject\venv\lib\site-packages\aiohttp\connector.py", line 917, in _resolve_host_with_throttle
    addrs = await self._resolver.resolve(host, port, family=self._family)
  File "C:\Users\ProPCUser\PycharmProjects\lycproject\venv\lib\site-packages\aiohttp\resolver.py", line 33, in resolve
    infos = await self._loop.getaddrinfo(
  File "C:\Users\ProPCUser\AppData\Local\Programs\Python\Python38\lib\asyncio\base_events.py", line 825, in getaddrinfo
    return await self.run_in_executor(
  File "C:\Users\ProPCUser\AppData\Local\Programs\Python\Python38\lib\concurrent\futures\thread.py", line 57, in run
    result = self.fn(*self.args, **self.kwargs)
  File "C:\Users\ProPCUser\AppData\Local\Programs\Python\Python38\lib\socket.py", line 918, in getaddrinfo
    for res in _socket.getaddrinfo(host, port, family, type, proto, flags):
socket.gaierror: [Errno 11001] getaddrinfo failed

The above exception was the direct cause of the following exception:

Traceback (most recent call last):
  File "C:\Users\ProPCUser\PycharmProjects\lycproject\venv\lib\site-packages\discord\client.py", line 656, in connect
    self.ws = await asyncio.wait_for(coro, timeout=60.0)
  File "C:\Users\ProPCUser\AppData\Local\Programs\Python\Python38\lib\asyncio\tasks.py", line 491, in wait_for
    return fut.result()
  File "C:\Users\ProPCUser\PycharmProjects\lycproject\venv\lib\site-packages\discord\gateway.py", line 372, in from_client
    socket = await client.http.ws_connect(str(url))
  File "C:\Users\ProPCUser\PycharmProjects\lycproject\venv\lib\site-packages\discord\http.py", line 537, in ws_connect
    return await self.__session.ws_connect(url, **kwargs)
  File "C:\Users\ProPCUser\PycharmProjects\lycproject\venv\lib\site-packages\aiohttp\client.py", line 835, in _ws_connect
    resp = await self.request(
  File "C:\Users\ProPCUser\PycharmProjects\lycproject\venv\lib\site-packages\aiohttp\client.py", line 581, in _request
    conn = await self._connector.connect(
  File "C:\Users\ProPCUser\PycharmProjects\lycproject\venv\lib\site-packages\aiohttp\connector.py", line 544, in connect
    proto = await self._create_connection(req, traces, timeout)
  File "C:\Users\ProPCUser\PycharmProjects\lycproject\venv\lib\site-packages\aiohttp\connector.py", line 944, in _create_connection
    _, proto = await self._create_direct_connection(req, traces, timeout)
  File "C:\Users\ProPCUser\PycharmProjects\lycproject\venv\lib\site-packages\aiohttp\connector.py", line 1209, in _create_direct_connection
    raise ClientConnectorError(req.connection_key, exc) from exc
aiohttp.client_exceptions.ClientConnectorError: Cannot connect to host gateway-us-east1-b.discord.gg:443 ssl:default [getaddrinfo failed]
Attempting a reconnect in 224.59s
Traceback (most recent call last):
  File "C:\Users\ProPCUser\PycharmProjects\lycproject\venv\lib\site-packages\aiohttp\connector.py", line 1203, in _create_direct_connection
    hosts = await self._resolve_host(host, port, traces=traces)
  File "C:\Users\ProPCUser\PycharmProjects\lycproject\venv\lib\site-packages\aiohttp\connector.py", line 880, in _resolve_host
    return await asyncio.shield(resolved_host_task)
  File "C:\Users\ProPCUser\PycharmProjects\lycproject\venv\lib\site-packages\aiohttp\connector.py", line 917, in _resolve_host_with_throttle
    addrs = await self._resolver.resolve(host, port, family=self._family)
  File "C:\Users\ProPCUser\PycharmProjects\lycproject\venv\lib\site-packages\aiohttp\resolver.py", line 33, in resolve
    infos = await self._loop.getaddrinfo(
  File "C:\Users\ProPCUser\AppData\Local\Programs\Python\Python38\lib\asyncio\base_events.py", line 825, in getaddrinfo
    return await self.run_in_executor(
  File "C:\Users\ProPCUser\AppData\Local\Programs\Python\Python38\lib\concurrent\futures\thread.py", line 57, in run
    result = self.fn(*self.args, **self.kwargs)
  File "C:\Users\ProPCUser\AppData\Local\Programs\Python\Python38\lib\socket.py", line 918, in getaddrinfo
    for res in _socket.getaddrinfo(host, port, family, type, proto, flags):
socket.gaierror: [Errno 11001] getaddrinfo failed

The above exception was the direct cause of the following exception:

Traceback (most recent call last):
  File "C:\Users\ProPCUser\PycharmProjects\lycproject\venv\lib\site-packages\discord\client.py", line 656, in connect
    self.ws = await asyncio.wait_for(coro, timeout=60.0)
  File "C:\Users\ProPCUser\AppData\Local\Programs\Python\Python38\lib\asyncio\tasks.py", line 491, in wait_for
    return fut.result()
  File "C:\Users\ProPCUser\PycharmProjects\lycproject\venv\lib\site-packages\discord\gateway.py", line 372, in from_client
    socket = await client.http.ws_connect(str(url))
  File "C:\Users\ProPCUser\PycharmProjects\lycproject\venv\lib\site-packages\discord\http.py", line 537, in ws_connect
    return await self.__session.ws_connect(url, **kwargs)
  File "C:\Users\ProPCUser\PycharmProjects\lycproject\venv\lib\site-packages\aiohttp\client.py", line 835, in _ws_connect
    resp = await self.request(
  File "C:\Users\ProPCUser\PycharmProjects\lycproject\venv\lib\site-packages\aiohttp\client.py", line 581, in _request
    conn = await self._connector.connect(
  File "C:\Users\ProPCUser\PycharmProjects\lycproject\venv\lib\site-packages\aiohttp\connector.py", line 544, in connect
    proto = await self._create_connection(req, traces, timeout)
  File "C:\Users\ProPCUser\PycharmProjects\lycproject\venv\lib\site-packages\aiohttp\connector.py", line 944, in _create_connection
    _, proto = await self._create_direct_connection(req, traces, timeout)
  File "C:\Users\ProPCUser\PycharmProjects\lycproject\venv\lib\site-packages\aiohttp\connector.py", line 1209, in _create_direct_connection
    raise ClientConnectorError(req.connection_key, exc) from exc
aiohttp.client_exceptions.ClientConnectorError: Cannot connect to host gateway-us-east1-b.discord.gg:443 ssl:default [getaddrinfo failed]
Ignoring exception in command 'abc'
Traceback (most recent call last):
  File "C:\Users\ProPCUser\PycharmProjects\lycproject\venv\lib\site-packages\discord\app_commands\commands.py", line 828, in _do_call
    return await self._callback(interaction, **params)  # type: ignore
  File "C:\Users\ProPCUser\PycharmProjects\lycproject\main.py", line 52, in test
    await interaction.response.send_message("Что ниибдуь", view=view, ephemeral=True)
  File "C:\Users\ProPCUser\PycharmProjects\lycproject\venv\lib\site-packages\discord\interactions.py", line 801, in send_message
    await adapter.create_interaction_response(
  File "C:\Users\ProPCUser\PycharmProjects\lycproject\venv\lib\site-packages\discord\webhook\async_.py", line 221, in request
    raise HTTPException(response, data)
discord.errors.HTTPException: 400 Bad Request (error code: 50035): Invalid Form Body
In data.components.0.components.0: Value of field "type" must be one of (2, 3, 5, 6, 7, 8).
In data.components.1.components.0: Value of field "type" must be one of (2, 3, 5, 6, 7, 8).
In data.components.2.components.0: Value of field "type" must be one of (2, 3, 5, 6, 7, 8).
In data.components.3.components.0: Value of field "type" must be one of (2, 3, 5, 6, 7, 8).
In data.components.4.components.0: Value of field "type" must be one of (2, 3, 5, 6, 7, 8).

The above exception was the direct cause of the following exception:

Traceback (most recent call last):
  File "C:\Users\ProPCUser\PycharmProjects\lycproject\venv\lib\site-packages\discord\app_commands\tree.py", line 1248, in _call
    await command._invoke_with_namespace(interaction, namespace)
  File "C:\Users\ProPCUser\PycharmProjects\lycproject\venv\lib\site-packages\discord\app_commands\commands.py", line 853, in _invoke_with_namespace
    return await self._do_call(interaction, transformed_values)
  File "C:\Users\ProPCUser\PycharmProjects\lycproject\venv\lib\site-packages\discord\app_commands\commands.py", line 846, in _do_call
    raise CommandInvokeError(self, e) from e
discord.app_commands.errors.CommandInvokeError: Command 'abc' raised an exception: HTTPException: 400 Bad Request (error code: 50035): Invalid Form Body
In data.components.0.components.0: Value of field "type" must be one of (2, 3, 5, 6, 7, 8).
In data.components.1.components.0: Value of field "type" must be one of (2, 3, 5, 6, 7, 8).
In data.components.2.components.0: Value of field "type" must be one of (2, 3, 5, 6, 7, 8).
In data.components.3.components.0: Value of field "type" must be one of (2, 3, 5, 6, 7, 8).
In data.components.4.components.0: Value of field "type" must be one of (2, 3, 5, 6, 7, 8).
Ignoring exception in command 'abc'
Traceback (most recent call last):
  File "C:\Users\ProPCUser\PycharmProjects\lycproject\venv\lib\site-packages\discord\app_commands\commands.py", line 828, in _do_call
    return await self._callback(interaction, **params)  # type: ignore
  File "C:\Users\ProPCUser\PycharmProjects\lycproject\main.py", line 52, in test
    await interaction.response.send_message("Что ниибдуь", view=view, ephemeral=True)
  File "C:\Users\ProPCUser\PycharmProjects\lycproject\venv\lib\site-packages\discord\interactions.py", line 801, in send_message
    await adapter.create_interaction_response(
  File "C:\Users\ProPCUser\PycharmProjects\lycproject\venv\lib\site-packages\discord\webhook\async_.py", line 221, in request
    raise HTTPException(response, data)
discord.errors.HTTPException: 400 Bad Request (error code: 50035): Invalid Form Body
In data.components.0.components.0: Value of field "type" must be one of (2, 3, 5, 6, 7, 8).
In data.components.1.components.0: Value of field "type" must be one of (2, 3, 5, 6, 7, 8).
In data.components.2.components.0: Value of field "type" must be one of (2, 3, 5, 6, 7, 8).

The above exception was the direct cause of the following exception:

Traceback (most recent call last):
  File "C:\Users\ProPCUser\PycharmProjects\lycproject\venv\lib\site-packages\discord\app_commands\tree.py", line 1248, in _call
    await command._invoke_with_namespace(interaction, namespace)
  File "C:\Users\ProPCUser\PycharmProjects\lycproject\venv\lib\site-packages\discord\app_commands\commands.py", line 853, in _invoke_with_namespace
    return await self._do_call(interaction, transformed_values)
  File "C:\Users\ProPCUser\PycharmProjects\lycproject\venv\lib\site-packages\discord\app_commands\commands.py", line 846, in _do_call
    raise CommandInvokeError(self, e) from e
discord.app_commands.errors.CommandInvokeError: Command 'abc' raised an exception: HTTPException: 400 Bad Request (error code: 50035): Invalid Form Body
In data.components.0.components.0: Value of field "type" must be one of (2, 3, 5, 6, 7, 8).
In data.components.1.components.0: Value of field "type" must be one of (2, 3, 5, 6, 7, 8).
In data.components.2.components.0: Value of field "type" must be one of (2, 3, 5, 6, 7, 8).
Ignoring exception in command 'abc'
Traceback (most recent call last):
  File "C:\Users\ProPCUser\PycharmProjects\lycproject\venv\lib\site-packages\discord\app_commands\commands.py", line 828, in _do_call
    return await self._callback(interaction, **params)  # type: ignore
  File "C:\Users\ProPCUser\PycharmProjects\lycproject\main.py", line 52, in test
    await interaction.response.send_message("Что ниибдуь", view=view, ephemeral=True)
  File "C:\Users\ProPCUser\PycharmProjects\lycproject\venv\lib\site-packages\discord\interactions.py", line 801, in send_message
    await adapter.create_interaction_response(
  File "C:\Users\ProPCUser\PycharmProjects\lycproject\venv\lib\site-packages\discord\webhook\async_.py", line 221, in request
    raise HTTPException(response, data)
discord.errors.HTTPException: 400 Bad Request (error code: 50035): Invalid Form Body
In data.components.0.components.0: Value of field "type" must be one of (2, 3, 5, 6, 7, 8).
In data.components.1.components.0: Value of field "type" must be one of (2, 3, 5, 6, 7, 8).
In data.components.2.components.0: Value of field "type" must be one of (2, 3, 5, 6, 7, 8).

The above exception was the direct cause of the following exception:

Traceback (most recent call last):
  File "C:\Users\ProPCUser\PycharmProjects\lycproject\venv\lib\site-packages\discord\app_commands\tree.py", line 1248, in _call
    await command._invoke_with_namespace(interaction, namespace)
  File "C:\Users\ProPCUser\PycharmProjects\lycproject\venv\lib\site-packages\discord\app_commands\commands.py", line 853, in _invoke_with_namespace
    return await self._do_call(interaction, transformed_values)
  File "C:\Users\ProPCUser\PycharmProjects\lycproject\venv\lib\site-packages\discord\app_commands\commands.py", line 846, in _do_call
    raise CommandInvokeError(self, e) from e
discord.app_commands.errors.CommandInvokeError: Command 'abc' raised an exception: HTTPException: 400 Bad Request (error code: 50035): Invalid Form Body
In data.components.0.components.0: Value of field "type" must be one of (2, 3, 5, 6, 7, 8).
In data.components.1.components.0: Value of field "type" must be one of (2, 3, 5, 6, 7, 8).
In data.components.2.components.0: Value of field "type" must be one of (2, 3, 5, 6, 7, 8).
Attempting a reconnect in 0.47s
Traceback (most recent call last):
  File "C:\Users\ProPCUser\PycharmProjects\lycproject\venv\lib\site-packages\discord\client.py", line 659, in connect
    await self.ws.poll_event()
  File "C:\Users\ProPCUser\PycharmProjects\lycproject\venv\lib\site-packages\discord\gateway.py", line 646, in poll_event
    raise ConnectionClosed(self.socket, shard_id=self.shard_id, code=code) from None
discord.errors.ConnectionClosed: Shard ID None WebSocket closed with 1000
Ignoring exception in command 'abc'
Traceback (most recent call last):
  File "C:\Users\ProPCUser\PycharmProjects\lycproject\venv\lib\site-packages\discord\app_commands\commands.py", line 828, in _do_call
    return await self._callback(interaction, **params)  # type: ignore
  File "C:\Users\ProPCUser\PycharmProjects\lycproject\main.py", line 52, in test
    await interaction.response.send_modal("Что ниибдуь", ephemeral=True)
TypeError: send_modal() got an unexpected keyword argument 'ephemeral'

The above exception was the direct cause of the following exception:

Traceback (most recent call last):
  File "C:\Users\ProPCUser\PycharmProjects\lycproject\venv\lib\site-packages\discord\app_commands\tree.py", line 1248, in _call
    await command._invoke_with_namespace(interaction, namespace)
  File "C:\Users\ProPCUser\PycharmProjects\lycproject\venv\lib\site-packages\discord\app_commands\commands.py", line 853, in _invoke_with_namespace
    return await self._do_call(interaction, transformed_values)
  File "C:\Users\ProPCUser\PycharmProjects\lycproject\venv\lib\site-packages\discord\app_commands\commands.py", line 842, in _do_call
    raise CommandInvokeError(self, e) from e
discord.app_commands.errors.CommandInvokeError: Command 'abc' raised an exception: TypeError: send_modal() got an unexpected keyword argument 'ephemeral'
Ignoring exception in modal <Schedule timeout=None children=4>:
Traceback (most recent call last):
  File "C:\Users\ProPCUser\PycharmProjects\lycproject\venv\lib\site-packages\discord\ui\modal.py", line 188, in _scheduled_task
    await self.on_submit(interaction)
  File "C:\Users\ProPCUser\PycharmProjects\lycproject\technical.py", line 34, in on_submit
    description=f"{interaction.guild.members.mention}, {author.mention} назначил встречу на "
AttributeError: 'SequenceProxy' object has no attribute 'mention'
Ignoring exception in modal <Schedule timeout=None children=4>:
Traceback (most recent call last):
  File "C:\Users\ProPCUser\PycharmProjects\lycproject\venv\lib\site-packages\discord\ui\modal.py", line 188, in _scheduled_task
    await self.on_submit(interaction)
  File "C:\Users\ProPCUser\PycharmProjects\lycproject\technical.py", line 35, in on_submit
    description=f"{interaction.guild.members.mention}, {author.mention} назначил встречу на "
AttributeError: 'SequenceProxy' object has no attribute 'mention'
Ignoring exception in modal <Schedule timeout=None children=4>:
Traceback (most recent call last):
  File "C:\Users\ProPCUser\PycharmProjects\lycproject\venv\lib\site-packages\discord\ui\modal.py", line 188, in _scheduled_task
    await self.on_submit(interaction)
  File "C:\Users\ProPCUser\PycharmProjects\lycproject\technical.py", line 36, in on_submit
    description=f"{mention} назначил встречу на "
  File "C:\Users\ProPCUser\AppData\Local\Programs\Python\Python38\lib\_strptime.py", line 568, in _strptime_datetime
    tt, fraction, gmtoff_fraction = _strptime(data_string, format)
  File "C:\Users\ProPCUser\AppData\Local\Programs\Python\Python38\lib\_strptime.py", line 349, in _strptime
    raise ValueError("time data %r does not match format %r" %
ValueError: time data '4' does not match format '%B'
Ignoring exception in modal <Schedule timeout=None children=4>:
Traceback (most recent call last):
  File "C:\Users\ProPCUser\PycharmProjects\lycproject\venv\lib\site-packages\discord\ui\modal.py", line 188, in _scheduled_task
    await self.on_submit(interaction)
  File "C:\Users\ProPCUser\PycharmProjects\lycproject\technical.py", line 43, in on_submit
    message = discord.Message(content="@everyone", embed=embed, allowed_mentions=allowed_mentions)
TypeError: __init__() got an unexpected keyword argument 'content'
Ignoring exception in modal <Schedule timeout=None children=4>:
Traceback (most recent call last):
  File "C:\Users\ProPCUser\PycharmProjects\lycproject\venv\lib\site-packages\discord\ui\modal.py", line 188, in _scheduled_task
    await self.on_submit(interaction)
  File "C:\Users\ProPCUser\PycharmProjects\lycproject\technical.py", line 43, in on_submit
    message = discord.Message(embed=embed, allowed_mentions=allowed_mentions)
TypeError: __init__() got an unexpected keyword argument 'embed'
Attempting a reconnect in 0.08s
Traceback (most recent call last):
  File "C:\Users\ProPCUser\PycharmProjects\lycproject\venv\lib\site-packages\discord\client.py", line 659, in connect
    await self.ws.poll_event()
  File "C:\Users\ProPCUser\PycharmProjects\lycproject\venv\lib\site-packages\discord\gateway.py", line 646, in poll_event
    raise ConnectionClosed(self.socket, shard_id=self.shard_id, code=code) from None
discord.errors.ConnectionClosed: Shard ID None WebSocket closed with 1000
Ignoring exception in modal <Schedule timeout=None children=4>:
Traceback (most recent call last):
  File "C:\Users\ProPCUser\PycharmProjects\lycproject\venv\lib\site-packages\discord\ui\modal.py", line 188, in _scheduled_task
    await self.on_submit(interaction)
  File "C:\Users\ProPCUser\PycharmProjects\lycproject\technical.py", line 45, in on_submit
    print(ff.id)
AttributeError: 'NoneType' object has no attribute 'id'
Ignoring exception in modal <Schedule timeout=None children=4>:
Traceback (most recent call last):
  File "C:\Users\ProPCUser\PycharmProjects\lycproject\venv\lib\site-packages\discord\ui\modal.py", line 188, in _scheduled_task
    await self.on_submit(interaction)
  File "C:\Users\ProPCUser\PycharmProjects\lycproject\technical.py", line 45, in on_submit
    print(ff.id)
AttributeError: 'NoneType' object has no attribute 'id'
Ignoring exception in modal <Schedule timeout=None children=4>:
Traceback (most recent call last):
  File "C:\Users\ProPCUser\PycharmProjects\lycproject\venv\lib\site-packages\discord\ui\modal.py", line 188, in _scheduled_task
    await self.on_submit(interaction)
  File "C:\Users\ProPCUser\PycharmProjects\lycproject\technical.py", line 46, in on_submit
    print(ff.id)
AttributeError: 'NoneType' object has no attribute 'id'
